# SYNTHETIC lastUpdateId=999999 GAP — pu mismatch injected at depth event 50 (expect exactly 1 resync)
# This fixture was synthetically generated. Real benchmark numbers must
# be captured from a live feed using tools/capture and regenerated.
{"ts_ns": 1725000000100000000, "stream": "depth", "msg": {"e": "depthUpdate", "E": 1725000000100, "s": "BTCUSDT", "U": 1000000, "u": 1000000, "pu": 999999, "b": [["64999.49", "0.41861379"], ["64999.51", "2.03009846"], ["64999.38", "1.63609960"]], "a": [["64999.63", "1.26576546"], ["64999.54", "0.28108572"]]}}
{"ts_ns": 1725000000141400793, "stream": "trade", "msg": {"e": "trade", "E": 1725000000100, "s": "BTCUSDT", "t": 10000000, "p": "64999.52", "q": "0.10021999", "m": false, "M": true, "T": 1725000000090}}
{"ts_ns": 1725000000200000000, "stream": "depth", "msg": {"e": "depthUpdate", "E": 1725000000200, "s": "BTCUSDT", "U": 1000001, "u": 1000002, "pu": 1000000, "b": [["64999.35", "2.41745776"], ["64999.36", "1.26784319"], ["64999.43", "0.46643850"]], "a": [["64999.61", "1.00978364"]]}}
{"ts_ns": 1725000000207490526, "stream": "trade", "msg": {"e": "trade", "E": 1725000000200, "s": "BTCUSDT", "t": 10000001, "p": "64999.48", "q": "0.17263391", "m": false, "M": true, "T": 1725000000190}}
{"ts_ns": 1725000000300000000, "stream": "depth", "msg": {"e": "depthUpdate", "E": 1725000000300, "s": "BTCUSDT", "U": 1000003, "u": 1000003, "pu": 1000002, "b": [["64999.56", "1.13560313"], ["64999.62", "0.87953484"], ["64999.60", "1.85555926"], ["64999.57", "1.08490508"], ["64999.67", "2.11371551"]], "a": [["64999.72", "1.98378996"]]}}
{"ts_ns": 1725000000400000000, "stream": "depth", "msg": {"e": "depthUpdate", "E": 1725000000400, "s": "BTCUSDT", "U": 1000004, "u": 1000004, "pu": 1000003, "b": [["65000.02", "1.36023091"]], "a": [["65000.21", "1.09449654"], ["65000.13", "1.06581210"], ["65000.18", "0.80093347"], ["65000.22", "2.05064300"]]}}
{"ts_ns": 1725000000443612671, "stream": "trade", "msg": {"e": "trade", "E": 1725000000400, "s": "BTCUSDT", "t": 10000002, "p": "65000.06", "q": "0.36483427", "m": true, "M": true, "T": 1725000000390}}
{"ts_ns": 1725000000500000000, "stream": "depth", "msg": {"e": "depthUpdate", "E": 1725000000500, "s": "BTCUSDT", "U": 1000005, "u": 1000008, "pu": 1000004, "b": [["64999.86", "0.65884552"], ["64999.89", "2.52855576"], ["64999.82", "0.16781384"], ["64999.81", "0.09630073"], ["64999.89", "1.20349436"], ["64999.93", "0.63294853"]], "a": [["65000.05", "2.62910288"], ["65000.01", "0.63787963"], ["65000.03", "1.18689570"], ["65000.10", "1.92855561"], ["64999.98", "0.79464050"], ["64999.99", "2.23496695"]]}}
{"ts_ns": 1725000000600000000, "stream": "depth", "msg": {"e": "depthUpdate", "E": 1725000000600, "s": "BTCUSDT", "U": 1000009, "u": 1000013, "pu": 1000008, "b": [["64999.82", "0.65796228"], ["64999.85", "1.52857888"], ["64999.86", "2.26734647"], ["64999.74", "0.32894739"], ["64999.77", "0.47994601"]], "a": [["64999.99", "1.26647990"], ["64999.90", "1.15430194"], ["64999.98", "2.98836414"], ["64999.97", "0.75424236"]]}}
{"ts_ns": 1725000000700000000, "stream": "depth", "msg": {"e": "depthUpdate", "E": 1725000000700, "s": "BTCUSDT", "U": 1000014, "u": 1000014, "pu": 1000013, "b": [["64999.91", "1.61091099"]], "a": [["65000.11", "2.30579620"], ["65000.12", "0.33465652"], ["65000.13", "0.47447326"], ["65000.07", "2.86144778"], ["65000.21", "2.15904201"], ["65000.15", "2.28588660"]]}}
{"ts_ns": 1725000000800000000, "stream": "depth", "msg": {"e": "depthUpdate", "E": 1725000000800, "s": "BTCUSDT", "U": 1000015, "u": 1000015, "pu": 1000014, "b": [["65000.34", "1.82691063"], ["65000.40", "1.12174156"], ["65000.40", "1.61813709"]], "a": [["65000.56", "2.76730224"], ["65000.58", "0.00171569"], ["65000.49", "1.46581712"], ["65000.45", "2.78729585"], ["65000.58", "2.95596414"], ["65000.56", "0.92254238"]]}}
{"ts_ns": 1725000000839074679, "stream": "trade", "msg": {"e": "trade", "E": 1725000000800, "s": "BTCUSDT", "t": 10000003, "p": "65000.44", "q": "0.04374107", "m": false, "M": true, "T": 1725000000790}}
{"ts_ns": 1725000000900000000, "stream": "depth", "msg": {"e": "depthUpdate", "E": 1725000000900, "s": "BTCUSDT", "U": 1000016, "u": 1000016, "pu": 1000015, "b": [["65000.88", "1.97925247"], ["65000.82", "0.49538088"], ["65000.82", "2.61729912"], ["65000.84", "2.89308872"], ["65000.76", "1.61788827"]], "a": [["65001.03", "2.06960290"], ["65001.03", "0.93514887"]]}}
{"ts_ns": 1725000001000000000, "stream": "depth", "msg": {"e": "depthUpdate", "E": 1725000001000, "s": "BTCUSDT", "U": 1000017, "u": 1000019, "pu": 1000016, "b": [["65000.83", "0.74371684"], ["65000.83", "1.01425669"], ["65000.75", "1.66176457"], ["65000.75", "0.66065215"], ["65000.83", "2.12352284"]], "a": [["65000.86", "0.68682535"], ["65001.00", "0.09423887"], ["65000.91", "0.21257205"], ["65000.89", "0.83543179"]]}}
{"ts_ns": 1725000001100000000, "stream": "depth", "msg": {"e": "depthUpdate", "E": 1725000001100, "s": "BTCUSDT", "U": 1000020, "u": 1000024, "pu": 1000019, "b": [["65000.40", "0.72899173"], ["65000.40", "2.42249099"], ["65000.44", "0.28297739"], ["65000.37", "1.29315355"], ["65000.41", "1.23330683"]], "a": [["65000.62", "2.18722755"], ["65000.59", "1.96036646"], ["65000.59", "0.29525361"], ["65000.55", "2.18464077"], ["65000.61", "2.58501761"]]}}
{"ts_ns": 1725000001113764703, "stream": "trade", "msg": {"e": "trade", "E": 1725000001100, "s": "BTCUSDT", "t": 10000004, "p": "65000.48", "q": "0.07095097", "m": true, "M": true, "T": 1725000001090}}
{"ts_ns": 1725000001200000000, "stream": "depth", "msg": {"e": "depthUpdate", "E": 1725000001200, "s": "BTCUSDT", "U": 1000025, "u": 1000027, "pu": 1000024, "b": [["65000.31", "2.58404731"]], "a": [["65000.53", "0.29372618"], ["65000.55", "2.99784741"], ["65000.58", "0.04427357"], ["65000.46", "2.77910095"]]}}
{"ts_ns": 1725000001300000000, "stream": "depth", "msg": {"e": "depthUpdate", "E": 1725000001300, "s": "BTCUSDT", "U": 1000028, "u": 1000029, "pu": 1000027, "b": [["65000.21", "1.20312088"], ["65000.34", "0.49391136"], ["65000.34", "2.95592653"], ["65000.30", "2.77955422"]], "a": [["65000.48", "1.36502510"], ["65000.42", "2.08977451"]]}}
{"ts_ns": 1725000001400000000, "stream": "depth", "msg": {"e": "depthUpdate", "E": 1725000001400, "s": "BTCUSDT", "U": 1000030, "u": 1000034, "pu": 1000029, "b": [["65000.47", "0.89012348"], ["65000.50", "1.73754087"], ["65000.42", "0.18287271"], ["65000.45", "0.17149582"]], "a": [["65000.61", "1.43036555"], ["65000.66", "2.55815968"]]}}
{"ts_ns": 1725000001435079793, "stream": "trade", "msg": {"e": "trade", "E": 1725000001400, "s": "BTCUSDT", "t": 10000005, "p": "65000.50", "q": "0.09372666", "m": true, "M": true, "T": 1725000001390}}
{"ts_ns": 1725000001500000000, "stream": "depth", "msg": {"e": "depthUpdate", "E": 1725000001500, "s": "BTCUSDT", "U": 1000035, "u": 1000036, "pu": 1000034, "b": [["65000.31", "1.78355746"], ["65000.31", "0.24595022"], ["65000.30", "1.75101687"], ["65000.32", "0.94910954"], ["65000.36", "0.61277760"]], "a": [["65000.53", "0.94255159"], ["65000.46", "1.18735754"]]}}
{"ts_ns": 1725000001600000000, "stream": "depth", "msg": {"e": "depthUpdate", "E": 1725000001600, "s": "BTCUSDT", "U": 1000037, "u": 1000039, "pu": 1000036, "b": [["65000.29", "1.86347777"]], "a": [["65000.47", "2.98828934"]]}}
{"ts_ns": 1725000001615304543, "stream": "trade", "msg": {"e": "trade", "E": 1725000001600, "s": "BTCUSDT", "t": 10000006, "p": "65000.37", "q": "0.06709583", "m": false, "M": true, "T": 1725000001590}}
{"ts_ns": 1725000001700000000, "stream": "depth", "msg": {"e": "depthUpdate", "E": 1725000001700, "s": "BTCUSDT", "U": 1000040, "u": 1000040, "pu": 1000039, "b": [["65000.72", "1.31455372"], ["65000.66", "2.11061978"], ["65000.65", "2.95155993"]], "a": [["65000.88", "1.96192895"], ["65000.76", "2.00358961"], ["65000.84", "0.89813626"]]}}
{"ts_ns": 1725000001800000000, "stream": "depth", "msg": {"e": "depthUpdate", "E": 1725000001800, "s": "BTCUSDT", "U": 1000041, "u": 1000042, "pu": 1000040, "b": [["65000.42", "0.46634373"]], "a": [["65000.56", "1.81448948"], ["65000.63", "1.02864086"], ["65000.62", "1.90271388"], ["65000.56", "1.51622717"], ["65000.56", "2.71600947"], ["65000.65", "0.15239668"]]}}
{"ts_ns": 1725000001900000000, "stream": "depth", "msg": {"e": "depthUpdate", "E": 1725000001900, "s": "BTCUSDT", "U": 1000043, "u": 1000045, "pu": 1000042, "b": [["64999.94", "2.93939386"], ["65000.02", "2.22369273"], ["64999.96", "2.11700234"]], "a": [["65000.14", "0.02900910"], ["65000.07", "2.83515282"]]}}
{"ts_ns": 1725000002000000000, "stream": "depth", "msg": {"e": "depthUpdate", "E": 1725000002000, "s": "BTCUSDT", "U": 1000046, "u": 1000047, "pu": 1000045, "b": [["65000.01", "0.44428136"], ["65000.07", "0.12548657"], ["65000.04", "2.69694447"]], "a": [["65000.23", "2.91658880"], ["65000.11", "2.69677391"], ["65000.14", "2.04620006"], ["65000.21", "0.30838087"], ["65000.23", "1.67965056"]]}}
{"ts_ns": 1725000002100000000, "stream": "depth", "msg": {"e": "depthUpdate", "E": 1725000002100, "s": "BTCUSDT", "U": 1000048, "u": 1000052, "pu": 1000047, "b": [["65000.22", "2.43231516"], ["65000.20", "1.23688323"]], "a": [["65000.38", "2.20969342"], ["65000.41", "2.34715949"]]}}
{"ts_ns": 1725000002200000000, "stream": "depth", "msg": {"e": "depthUpdate", "E": 1725000002200, "s": "BTCUSDT", "U": 1000053, "u": 1000054, "pu": 1000052, "b": [["65000.05", "2.61650035"], ["64999.98", "1.41207006"], ["65000.08", "2.44975982"], ["65000.04", "1.04897527"], ["64999.98", "2.38603650"], ["65000.08", "0.66877064"]], "a": [["65000.23", "0.57938936"]]}}
{"ts_ns": 1725000002205658747, "stream": "trade", "msg": {"e": "trade", "E": 1725000002200, "s": "BTCUSDT", "t": 10000007, "p": "65000.13", "q": "0.14028337", "m": false, "M": true, "T": 1725000002190}}
{"ts_ns": 1725000002300000000, "stream": "depth", "msg": {"e": "depthUpdate", "E": 1725000002300, "s": "BTCUSDT", "U": 1000055, "u": 1000059, "pu": 1000054, "b": [["64999.80", "2.91120183"]], "a": [["64999.98", "1.74176920"]]}}
{"ts_ns": 1725000002400000000, "stream": "depth", "msg": {"e": "depthUpdate", "E": 1725000002400, "s": "BTCUSDT", "U": 1000060, "u": 1000060, "pu": 1000059, "b": [["64999.44", "2.35928453"], ["64999.49", "1.81862656"], ["64999.47", "0.34693735"], ["64999.41", "1.72976413"]], "a": [["64999.61", "0.13315960"], ["64999.63", "0.00507383"], ["64999.71", "2.41953261"]]}}
{"ts_ns": 1725000002500000000, "stream": "depth", "msg": {"e": "depthUpdate", "E": 1725000002500, "s": "BTCUSDT", "U": 1000061, "u": 1000062, "pu": 1000060, "b": [["64999.27", "0.99060011"]], "a": [["64999.48", "1.99016243"], ["64999.44", "2.15926279"], ["64999.47", "1.52136751"], ["64999.53", "1.22517873"], ["64999.49", "2.09162524"], ["64999.51", "0.38186340"]]}}
{"ts_ns": 1725000002600000000, "stream": "depth", "msg": {"e": "depthUpdate", "E": 1725000002600, "s": "BTCUSDT", "U": 1000063, "u": 1000066, "pu": 1000062, "b": [["64999.50", "0.90284962"], ["64999.51", "2.50117551"]], "a": [["64999.65", "0.86074115"], ["64999.67", "2.35727648"], ["64999.70", "1.96411687"], ["64999.68", "1.32535805"], ["64999.71", "0.64110420"]]}}
{"ts_ns": 1725000002700000000, "stream": "depth", "msg": {"e": "depthUpdate", "E": 1725000002700, "s": "BTCUSDT", "U": 1000067, "u": 1000068, "pu": 1000066, "b": [["64999.65", "1.89882257"], ["64999.70", "0.28016160"], ["64999.63", "0.70460580"]], "a": [["64999.81", "0.67392200"], ["64999.80", "0.44206189"], ["64999.77", "0.73452763"], ["64999.84", "1.83382192"], ["64999.89", "0.21848469"]]}}
{"ts_ns": 1725000002800000000, "stream": "depth", "msg": {"e": "depthUpdate", "E": 1725000002800, "s": "BTCUSDT", "U": 1000069, "u": 1000073, "pu": 1000068, "b": [["64999.37", "1.19895859"], ["64999.42", "1.96817403"], ["64999.44", "2.67797948"], ["64999.31", "2.31013857"], ["64999.43", "2.33526122"], ["64999.41", "0.52766005"]], "a": [["64999.57", "1.55387325"], ["64999.46", "1.67221738"], ["64999.60", "2.54500904"], ["64999.53", "0.40001732"]]}}
{"ts_ns": 1725000002900000000, "stream": "depth", "msg": {"e": "depthUpdate", "E": 1725000002900, "s": "BTCUSDT", "U": 1000074, "u": 1000078, "pu": 1000073, "b": [["64999.81", "2.67427778"], ["64999.84", "2.44501952"], ["64999.79", "1.51433449"], ["64999.80", "2.72056419"], ["64999.86", "2.69162431"]], "a": [["65000.06", "2.58448473"], ["65000.02", "0.77757465"], ["64999.98", "2.51958866"]]}}
{"ts_ns": 1725000002935983838, "stream": "trade", "msg": {"e": "trade", "E": 1725000002900, "s": "BTCUSDT", "t": 10000008, "p": "64999.94", "q": "0.12038369", "m": false, "M": true, "T": 1725000002890}}
{"ts_ns": 1725000003000000000, "stream": "depth", "msg": {"e": "depthUpdate", "E": 1725000003000, "s": "BTCUSDT", "U": 1000079, "u": 1000079, "pu": 1000078, "b": [["65000.09", "0.95912871"], ["65000.06", "0.24173297"]], "a": [["65000.18", "0.69378444"], ["65000.27", "0.45841580"], ["65000.19", "0.19268655"]]}}
{"ts_ns": 1725000003100000000, "stream": "depth", "msg": {"e": "depthUpdate", "E": 1725000003100, "s": "BTCUSDT", "U": 1000080, "u": 1000084, "pu": 1000079, "b": [["64999.98", "1.26043055"]], "a": [["65000.27", "2.30938732"], ["65000.24", "0.05859587"]]}}
{"ts_ns": 1725000003200000000, "stream": "depth", "msg": {"e": "depthUpdate", "E": 1725000003200, "s": "BTCUSDT", "U": 1000085, "u": 1000089, "pu": 1000084, "b": [["64999.95", "2.26042538"]], "a": [["65000.14", "2.67492463"], ["65000.14", "1.25706385"], ["65000.12", "2.20390218"]]}}
{"ts_ns": 1725000003300000000, "stream": "depth", "msg": {"e": "depthUpdate", "E": 1725000003300, "s": "BTCUSDT", "U": 1000090, "u": 1000091, "pu": 1000089, "b": [["64999.91", "0.08707446"], ["64999.93", "2.00662086"], ["64999.86", "1.21295001"]], "a": [["65000.02", "2.52151699"], ["65000.14", "0.38288339"], ["65000.09", "1.60237089"], ["65000.14", "1.18206077"]]}}
{"ts_ns": 1725000003400000000, "stream": "depth", "msg": {"e": "depthUpdate", "E": 1725000003400, "s": "BTCUSDT", "U": 1000092, "u": 1000092, "pu": 1000091, "b": [["64999.43", "1.38509533"], ["64999.56", "0.78046894"], ["64999.51", "0.63498085"], ["64999.51", "1.01250164"]], "a": [["64999.72", "1.13737865"], ["64999.70", "2.85361236"]]}}
{"ts_ns": 1725000003500000000, "stream": "depth", "msg": {"e": "depthUpdate", "E": 1725000003500, "s": "BTCUSDT", "U": 1000093, "u": 1000093, "pu": 1000092, "b": [["64999.53", "2.99972349"], ["64999.48", "0.67266650"], ["64999.52", "2.34369915"], ["64999.43", "0.12077441"], ["64999.53", "2.84883520"], ["64999.50", "2.51768654"]], "a": [["64999.64", "0.45714704"], ["64999.57", "1.42068318"], ["64999.56", "1.69190875"], ["64999.58", "1.39510195"], ["64999.59", "2.30069430"]]}}
{"ts_ns": 1725000003541751689, "stream": "trade", "msg": {"e": "trade", "E": 1725000003500, "s": "BTCUSDT", "t": 10000009, "p": "64999.55", "q": "0.35946026", "m": true, "M": true, "T": 1725000003490}}
{"ts_ns": 1725000003600000000, "stream": "depth", "msg": {"e": "depthUpdate", "E": 1725000003600, "s": "BTCUSDT", "U": 1000094, "u": 1000096, "pu": 1000093, "b": [["64999.05", "2.03204186"]], "a": [["64999.22", "1.18996332"], ["64999.27", "0.59498933"], ["64999.25", "2.07184325"]]}}
{"ts_ns": 1725000003700000000, "stream": "depth", "msg": {"e": "depthUpdate", "E": 1725000003700, "s": "BTCUSDT", "U": 1000097, "u": 1000097, "pu": 1000096, "b": [["64999.25", "2.41658389"], ["64999.22", "2.95153305"], ["64999.22", "0.12320739"]], "a": [["64999.44", "1.28513404"], ["64999.41", "0.20687021"], ["64999.46", "1.02369352"], ["64999.49", "1.26017622"], ["64999.43", "0.31661661"], ["64999.41", "1.90675532"]]}}
{"ts_ns": 1725000003800000000, "stream": "depth", "msg": {"e": "depthUpdate", "E": 1725000003800, "s": "BTCUSDT", "U": 1000098, "u": 1000099, "pu": 1000097, "b": [["64999.18", "0.81024719"], ["64999.16", "2.75885297"], ["64999.16", "1.45049251"], ["64999.22", "2.47720380"], ["64999.19", "0.80518661"], ["64999.15", "0.73648551"]], "a": [["64999.44", "0.25998869"], ["64999.44", "1.35240600"], ["64999.42", "1.39412540"], ["64999.39", "2.00456541"], ["64999.35", "0.08609999"]]}}
{"ts_ns": 1725000003900000000, "stream": "depth", "msg": {"e": "depthUpdate", "E": 1725000003900, "s": "BTCUSDT", "U": 1000100, "u": 1000101, "pu": 1000099, "b": [["64999.22", "0.83897546"], ["64999.18", "2.10355125"], ["64999.23", "1.66737308"]], "a": [["64999.37", "2.84418773"], ["64999.30", "0.72406815"], ["64999.35", "1.46573354"]]}}
{"ts_ns": 1725000004000000000, "stream": "depth", "msg": {"e": "depthUpdate", "E": 1725000004000, "s": "BTCUSDT", "U": 1000102, "u": 1000105, "pu": 1000101, "b": [["64999.30", "0.05172978"], ["64999.38", "0.66478920"], ["64999.31", "0.72991549"], ["64999.32", "1.74466676"]], "a": [["64999.51", "1.66041887"], ["64999.49", "1.27651144"], ["64999.55", "1.65116542"], ["64999.49", "2.10856483"]]}}
{"ts_ns": 1725000004017871415, "stream": "trade", "msg": {"e": "trade", "E": 1725000004000, "s": "BTCUSDT", "t": 10000010, "p": "64999.42", "q": "0.36092088", "m": false, "M": true, "T": 1725000003990}}
{"ts_ns": 1725000004100000000, "stream": "depth", "msg": {"e": "depthUpdate", "E": 1725000004100, "s": "BTCUSDT", "U": 1000106, "u": 1000106, "pu": 1000105, "b": [["64999.63", "0.64915392"], ["64999.59", "0.82949888"], ["64999.57", "2.92982107"], ["64999.58", "1.79037222"], ["64999.65", "2.49788509"], ["64999.62", "0.68244949"]], "a": [["64999.70", "0.90680277"], ["64999.79", "1.60240527"]]}}
{"ts_ns": 1725000004104659179, "stream": "trade", "msg": {"e": "trade", "E": 1725000004100, "s": "BTCUSDT", "t": 10000011, "p": "64999.67", "q": "0.34901128", "m": true, "M": true, "T": 1725000004090}}
{"ts_ns": 1725000004200000000, "stream": "depth", "msg": {"e": "depthUpdate", "E": 1725000004200, "s": "BTCUSDT", "U": 1000107, "u": 1000110, "pu": 1000106, "b": [["64999.22", "1.40819083"]], "a": [["64999.35", "1.02211780"], ["64999.28", "0.75743517"], ["64999.41", "1.43318756"], ["64999.41", "0.19603031"], ["64999.35", "0.22224651"]]}}
{"ts_ns": 1725000004300000000, "stream": "depth", "msg": {"e": "depthUpdate", "E": 1725000004300, "s": "BTCUSDT", "U": 1000111, "u": 1000111, "pu": 1000110, "b": [["64998.90", "2.98175437"], ["64998.90", "1.67421910"], ["64998.85", "1.81895295"], ["64998.79", "1.85525506"], ["64998.79", "1.56771761"]], "a": [["64999.00", "2.72551313"], ["64998.97", "2.58050000"], ["64998.99", "0.91614073"]]}}
{"ts_ns": 1725000004400000000, "stream": "depth", "msg": {"e": "depthUpdate", "E": 1725000004400, "s": "BTCUSDT", "U": 1000112, "u": 1000116, "pu": 1000111, "b": [["64999.27", "0.63307559"]], "a": [["64999.49", "0.24356240"], ["64999.42", "0.52144064"]]}}
{"ts_ns": 1725000004401179564, "stream": "trade", "msg": {"e": "trade", "E": 1725000004400, "s": "BTCUSDT", "t": 10000012, "p": "64999.38", "q": "0.34499620", "m": false, "M": true, "T": 1725000004390}}
{"ts_ns": 1725000004500000000, "stream": "depth", "msg": {"e": "depthUpdate", "E": 1725000004500, "s": "BTCUSDT", "U": 1000117, "u": 1000119, "pu": 1000116, "b": [["64998.86", "2.10896267"], ["64998.83", "0.21353928"], ["64998.87", "2.77173313"]], "a": [["64999.04", "2.37374324"], ["64999.01", "1.98354913"], ["64999.06", "0.59345764"], ["64998.93", "1.63368714"], ["64999.02", "0.44696820"], ["64998.96", "2.47989348"]]}}
{"ts_ns": 1725000004512134889, "stream": "trade", "msg": {"e": "trade", "E": 1725000004500, "s": "BTCUSDT", "t": 10000013, "p": "64998.92", "q": "0.29792697", "m": false, "M": true, "T": 1725000004490}}
{"ts_ns": 1725000004600000000, "stream": "depth", "msg": {"e": "depthUpdate", "E": 1725000004600, "s": "BTCUSDT", "U": 1000120, "u": 1000123, "pu": 1000119, "b": [["64998.41", "1.20752556"], ["64998.48", "1.50141653"], ["64998.45", "1.31327659"], ["64998.43", "0.11958235"], ["64998.46", "2.20360177"], ["64998.43", "0.75110371"]], "a": [["64998.55", "0.68677325"], ["64998.64", "2.50787584"], ["64998.63", "1.76136880"]]}}
{"ts_ns": 1725000004646116053, "stream": "trade", "msg": {"e": "trade", "E": 1725000004600, "s": "BTCUSDT", "t": 10000014, "p": "64998.54", "q": "0.28854725", "m": true, "M": true, "T": 1725000004590}}
{"ts_ns": 1725000004700000000, "stream": "depth", "msg": {"e": "depthUpdate", "E": 1725000004700, "s": "BTCUSDT", "U": 1000124, "u": 1000127, "pu": 1000123, "b": [["64998.52", "2.99083642"], ["64998.48", "1.90435416"], ["64998.47", "2.90716571"], ["64998.47", "1.04388317"]], "a": [["64998.61", "0.96317477"], ["64998.57", "2.57319928"], ["64998.61", "1.23493527"]]}}
{"ts_ns": 1725000004800000000, "stream": "depth", "msg": {"e": "depthUpdate", "E": 1725000004800, "s": "BTCUSDT", "U": 1000128, "u": 1000131, "pu": 1000127, "b": [["64998.78", "0.26417938"], ["64998.81", "0.96982136"], ["64998.73", "1.21252517"], ["64998.77", "2.47478161"], ["64998.85", "1.97298116"]], "a": [["64998.95", "1.38592903"]]}}
{"ts_ns": 1725000004835791878, "stream": "trade", "msg": {"e": "trade", "E": 1725000004800, "s": "BTCUSDT", "t": 10000015, "p": "64998.86", "q": "0.37846513", "m": false, "M": true, "T": 1725000004790}}
{"ts_ns": 1725000004900000000, "stream": "depth", "msg": {"e": "depthUpdate", "E": 1725000004900, "s": "BTCUSDT", "U": 1000132, "u": 1000132, "pu": 1000131, "b": [["64998.41", "0.86408743"], ["64998.41", "2.09475009"], ["64998.54", "0.08660833"], ["64998.45", "1.82661500"], ["64998.52", "2.12934848"]], "a": [["64998.61", "1.65251702"], ["64998.65", "1.22397206"]]}}
{"ts_ns": 1725000004908614246, "stream": "trade", "msg": {"e": "trade", "E": 1725000004900, "s": "BTCUSDT", "t": 10000016, "p": "64998.56", "q": "0.05961561", "m": true, "M": true, "T": 1725000004890}}
{"ts_ns": 1725000005000000000, "stream": "depth", "msg": {"e": "depthUpdate", "E": 1725000005000, "s": "BTCUSDT", "U": 1000133, "u": 1000136, "pu": 1001131, "b": [["64998.87", "0.82027469"], ["64998.85", "1.44749873"], ["64998.91", "0.73119272"]], "a": [["64999.08", "0.43392591"], ["64999.03", "2.76560445"], ["64999.08", "2.23887764"], ["64999.02", "2.59208080"], ["64999.04", "2.31802540"]]}}
{"ts_ns": 1725000005100000000, "stream": "depth", "msg": {"e": "depthUpdate", "E": 1725000005100, "s": "BTCUSDT", "U": 1000137, "u": 1000139, "pu": 1000136, "b": [["64999.28", "0.00769578"], ["64999.30", "0.89566755"], ["64999.32", "1.73977015"], ["64999.31", "1.46892104"], ["64999.39", "1.33964218"]], "a": [["64999.50", "1.03537183"], ["64999.51", "2.28861803"], ["64999.49", "1.36603385"]]}}
{"ts_ns": 1725000005113660246, "stream": "trade", "msg": {"e": "trade", "E": 1725000005100, "s": "BTCUSDT", "t": 10000017, "p": "64999.43", "q": "0.12016397", "m": false, "M": true, "T": 1725000005090}}
{"ts_ns": 1725000005200000000, "stream": "depth", "msg": {"e": "depthUpdate", "E": 1725000005200, "s": "BTCUSDT", "U": 1000140, "u": 1000141, "pu": 1000139, "b": [["64999.72", "2.23411545"], ["64999.66", "2.74029050"], ["64999.71", "1.15823626"], ["64999.67", "2.37718098"]], "a": [["64999.89", "2.94245442"]]}}
{"ts_ns": 1725000005300000000, "stream": "depth", "msg": {"e": "depthUpdate", "E": 1725000005300, "s": "BTCUSDT", "U": 1000142, "u": 1000142, "pu": 1000141, "b": [["64999.27", "0.30109381"], ["64999.27", "1.32091863"], ["64999.32", "2.73132503"], ["64999.40", "2.16733148"], ["64999.34", "2.61279891"]], "a": [["64999.44", "0.22448474"], ["64999.54", "2.90761089"], ["64999.47", "1.86977820"]]}}
{"ts_ns": 1725000005306389869, "stream": "trade", "msg": {"e": "trade", "E": 1725000005300, "s": "BTCUSDT", "t": 10000018, "p": "64999.42", "q": "0.42631833", "m": false, "M": true, "T": 1725000005290}}
{"ts_ns": 1725000005400000000, "stream": "depth", "msg": {"e": "depthUpdate", "E": 1725000005400, "s": "BTCUSDT", "U": 1000143, "u": 1000145, "pu": 1000142, "b": [["64999.53", "1.85237838"], ["64999.50", "1.89348305"], ["64999.39", "0.86213701"], ["64999.50", "2.24029910"]], "a": [["64999.61", "2.93501318"], ["64999.67", "1.90124349"], ["64999.68", "0.30152172"], ["64999.57", "2.08200349"], ["64999.69", "0.08684175"]]}}
{"ts_ns": 1725000005404766097, "stream": "trade", "msg": {"e": "trade", "E": 1725000005400, "s": "BTCUSDT", "t": 10000019, "p": "64999.54", "q": "0.18804570", "m": true, "M": true, "T": 1725000005390}}
{"ts_ns": 1725000005500000000, "stream": "depth", "msg": {"e": "depthUpdate", "E": 1725000005500, "s": "BTCUSDT", "U": 1000146, "u": 1000147, "pu": 1000145, "b": [["64999.44", "0.54017066"], ["64999.54", "0.23690505"], ["64999.43", "1.14763290"], ["64999.46", "0.72248938"], ["64999.42", "1.74947139"]], "a": [["64999.61", "1.38344974"], ["64999.62", "1.37871150"], ["64999.68", "0.02819229"], ["64999.70", "1.39575977"], ["64999.62", "2.03283266"], ["64999.60", "0.22158570"]]}}
{"ts_ns": 1725000005600000000, "stream": "depth", "msg": {"e": "depthUpdate", "E": 1725000005600, "s": "BTCUSDT", "U": 1000148, "u": 1000152, "pu": 1000147, "b": [["64999.32", "1.37050744"], ["64999.32", "0.59765100"], ["64999.30", "2.56000638"], ["64999.35", "0.71161711"]], "a": [["64999.47", "1.07687747"], ["64999.42", "2.97807613"], ["64999.42", "0.06581879"], ["64999.51", "1.97468945"], ["64999.42", "0.02429390"], ["64999.51", "2.05739848"]]}}
{"ts_ns": 1725000005700000000, "stream": "depth", "msg": {"e": "depthUpdate", "E": 1725000005700, "s": "BTCUSDT", "U": 1000153, "u": 1000153, "pu": 1000152, "b": [["64999.64", "2.71246587"], ["64999.73", "2.32722294"], ["64999.74", "1.82119499"], ["64999.72", "0.65701362"], ["64999.74", "1.86267349"], ["64999.67", "2.26673197"]], "a": [["64999.91", "1.97754462"], ["64999.92", "0.41033772"], ["64999.80", "2.71021111"], ["64999.89", "0.11826772"]]}}
{"ts_ns": 1725000005800000000, "stream": "depth", "msg": {"e": "depthUpdate", "E": 1725000005800, "s": "BTCUSDT", "U": 1000154, "u": 1000154, "pu": 1000153, "b": [["64999.84", "2.72888344"], ["64999.80", "2.24244259"], ["64999.83", "0.60238438"], ["64999.73", "1.61822328"], ["64999.80", "1.59255712"], ["64999.71", "0.81758205"]], "a": [["64999.89", "0.77091025"], ["65000.00", "2.83256345"]]}}
{"ts_ns": 1725000005900000000, "stream": "depth", "msg": {"e": "depthUpdate", "E": 1725000005900, "s": "BTCUSDT", "U": 1000155, "u": 1000157, "pu": 1000154, "b": [["65000.03", "2.88867988"], ["65000.08", "2.26245448"], ["65000.07", "2.58042179"]], "a": [["65000.23", "2.02321869"]]}}
{"ts_ns": 1725000005938400616, "stream": "trade", "msg": {"e": "trade", "E": 1725000005900, "s": "BTCUSDT", "t": 10000020, "p": "65000.11", "q": "0.39555030", "m": true, "M": true, "T": 1725000005890}}
{"ts_ns": 1725000006000000000, "stream": "depth", "msg": {"e": "depthUpdate", "E": 1725000006000, "s": "BTCUSDT", "U": 1000158, "u": 1000160, "pu": 1000157, "b": [["65000.04", "2.24703481"], ["65000.10", "1.75368027"], ["65000.01", "1.91564780"], ["65000.09", "0.32503831"]], "a": [["65000.19", "1.41443060"], ["65000.25", "2.65270454"], ["65000.24", "0.98401885"]]}}
{"ts_ns": 1725000006100000000, "stream": "depth", "msg": {"e": "depthUpdate", "E": 1725000006100, "s": "BTCUSDT", "U": 1000161, "u": 1000161, "pu": 1000160, "b": [["65000.24", "1.94771834"], ["65000.27", "0.41933104"], ["65000.28", "0.91309375"], ["65000.21", "0.34836144"]], "a": [["65000.33", "2.66177793"], ["65000.32", "1.16593749"], ["65000.35", "2.01145866"], ["65000.41", "2.08945197"], ["65000.38", "1.25738026"], ["65000.41", "2.17979745"]]}}
{"ts_ns": 1725000006200000000, "stream": "depth", "msg": {"e": "depthUpdate", "E": 1725000006200, "s": "BTCUSDT", "U": 1000162, "u": 1000162, "pu": 1000161, "b": [["65000.57", "0.09814886"], ["65000.56", "0.65180905"], ["65000.54", "2.85166551"], ["65000.48", "1.08805812"], ["65000.51", "1.10200488"]], "a": [["65000.77", "2.93352759"], ["65000.68", "0.18165027"], ["65000.67", "0.56942569"], ["65000.64", "2.84703236"]]}}
{"ts_ns": 1725000006300000000, "stream": "depth", "msg": {"e": "depthUpdate", "E": 1725000006300, "s": "BTCUSDT", "U": 1000163, "u": 1000163, "pu": 1000162, "b": [["65000.68", "2.91327994"], ["65000.77", "2.36038377"], ["65000.74", "2.96646271"], ["65000.65", "1.69373393"], ["65000.76", "2.48945351"], ["65000.69", "0.62147211"]], "a": [["65000.82", "2.43915894"], ["65000.82", "0.98567866"], ["65000.81", "2.36593126"], ["65000.88", "0.00850665"], ["65000.92", "2.95208440"], ["65000.81", "1.62064637"]]}}
{"ts_ns": 1725000006400000000, "stream": "depth", "msg": {"e": "depthUpdate", "E": 1725000006400, "s": "BTCUSDT", "U": 1000164, "u": 1000164, "pu": 1000163, "b": [["65000.93", "1.07472684"]], "a": [["65001.07", "0.71379482"], ["65001.00", "0.04734325"]]}}
{"ts_ns": 1725000006409506621, "stream": "trade", "msg": {"e": "trade", "E": 1725000006400, "s": "BTCUSDT", "t": 10000021, "p": "65000.94", "q": "0.26351668", "m": true, "M": true, "T": 1725000006390}}
{"ts_ns": 1725000006500000000, "stream": "depth", "msg": {"e": "depthUpdate", "E": 1725000006500, "s": "BTCUSDT", "U": 1000165, "u": 1000168, "pu": 1000164, "b": [["65000.79", "0.32716203"], ["65000.80", "0.66464927"], ["65000.79", "0.13009511"]], "a": [["65001.02", "2.72625506"], ["65001.00", "1.56435364"], ["65000.97", "1.93002205"], ["65000.90", "0.18247622"], ["65000.97", "2.54189563"]]}}
{"ts_ns": 1725000006600000000, "stream": "depth", "msg": {"e": "depthUpdate", "E": 1725000006600, "s": "BTCUSDT", "U": 1000169, "u": 1000169, "pu": 1000168, "b": [["65000.73", "0.24237143"], ["65000.78", "0.44500148"], ["65000.85", "0.82504800"], ["65000.77", "1.75609407"]], "a": [["65001.00", "0.97555633"]]}}
{"ts_ns": 1725000006700000000, "stream": "depth", "msg": {"e": "depthUpdate", "E": 1725000006700, "s": "BTCUSDT", "U": 1000170, "u": 1000174, "pu": 1000169, "b": [["65000.60", "0.29753539"], ["65000.55", "0.34324222"], ["65000.56", "1.95274999"], ["65000.54", "1.65400569"], ["65000.53", "0.64506920"]], "a": [["65000.75", "2.66427307"], ["65000.74", "1.01679486"], ["65000.75", "1.19619055"], ["65000.79", "0.28525752"], ["65000.74", "0.93757071"]]}}
{"ts_ns": 1725000006711243424, "stream": "trade", "msg": {"e": "trade", "E": 1725000006700, "s": "BTCUSDT", "t": 10000022, "p": "65000.67", "q": "0.23765967", "m": true, "M": true, "T": 1725000006690}}
{"ts_ns": 1725000006800000000, "stream": "depth", "msg": {"e": "depthUpdate", "E": 1725000006800, "s": "BTCUSDT", "U": 1000175, "u": 1000175, "pu": 1000174, "b": [["65000.14", "1.11794058"]], "a": [["65000.29", "1.66911221"], ["65000.36", "2.86987387"], ["65000.35", "0.98893794"], ["65000.28", "1.23242590"], ["65000.40", "1.99602156"], ["65000.39", "1.26881057"]]}}
{"ts_ns": 1725000006900000000, "stream": "depth", "msg": {"e": "depthUpdate", "E": 1725000006900, "s": "BTCUSDT", "U": 1000176, "u": 1000176, "pu": 1000175, "b": [["65000.67", "0.31080170"], ["65000.64", "0.63821642"], ["65000.62", "1.44656819"], ["65000.59", "0.32465515"], ["65000.59", "1.66879643"]], "a": [["65000.75", "2.28781690"], ["65000.83", "0.67847728"], ["65000.80", "2.53546548"]]}}
{"ts_ns": 1725000007000000000, "stream": "depth", "msg": {"e": "depthUpdate", "E": 1725000007000, "s": "BTCUSDT", "U": 1000177, "u": 1000181, "pu": 1000176, "b": [["65000.83", "1.82698475"], ["65000.73", "2.48838237"], ["65000.79", "0.08685954"], ["65000.79", "2.10809632"], ["65000.79", "2.76461256"], ["65000.78", "0.01831737"]], "a": [["65000.98", "0.42975447"], ["65000.95", "1.20235303"], ["65000.87", "2.22290718"], ["65000.85", "0.27527305"], ["65000.93", "0.64539864"]]}}
{"ts_ns": 1725000007100000000, "stream": "depth", "msg": {"e": "depthUpdate", "E": 1725000007100, "s": "BTCUSDT", "U": 1000182, "u": 1000184, "pu": 1000181, "b": [["65000.44", "2.33050686"], ["65000.40", "1.78867132"], ["65000.35", "0.15782648"]], "a": [["65000.53", "2.26330764"], ["65000.51", "2.02190613"], ["65000.55", "1.32933892"], ["65000.57", "1.45698511"], ["65000.58", "1.24255121"], ["65000.54", "2.26482943"]]}}
{"ts_ns": 1725000007129851015, "stream": "trade", "msg": {"e": "trade", "E": 1725000007100, "s": "BTCUSDT", "t": 10000023, "p": "65000.49", "q": "0.33943073", "m": false, "M": true, "T": 1725000007090}}
{"ts_ns": 1725000007200000000, "stream": "depth", "msg": {"e": "depthUpdate", "E": 1725000007200, "s": "BTCUSDT", "U": 1000185, "u": 1000189, "pu": 1000184, "b": [["65000.60", "2.95333697"]], "a": [["65000.68", "0.02306126"], ["65000.72", "2.83597226"]]}}
{"ts_ns": 1725000007300000000, "stream": "depth", "msg": {"e": "depthUpdate", "E": 1725000007300, "s": "BTCUSDT", "U": 1000190, "u": 1000192, "pu": 1000189, "b": [["65000.38", "2.24104237"]], "a": [["65000.49", "0.38755711"]]}}
{"ts_ns": 1725000007400000000, "stream": "depth", "msg": {"e": "depthUpdate", "E": 1725000007400, "s": "BTCUSDT", "U": 1000193, "u": 1000194, "pu": 1000192, "b": [["65000.44", "1.19121352"], ["65000.34", "0.12690678"], ["65000.45", "1.37926275"], ["65000.44", "2.58633004"], ["65000.36", "1.28785286"], ["65000.39", "2.12849688"]], "a": [["65000.53", "0.86854562"], ["65000.53", "0.06256968"], ["65000.52", "0.51561954"]]}}
{"ts_ns": 1725000007500000000, "stream": "depth", "msg": {"e": "depthUpdate", "E": 1725000007500, "s": "BTCUSDT", "U": 1000195, "u": 1000198, "pu": 1000194, "b": [["65000.72", "2.53345308"], ["65000.75", "1.30702958"], ["65000.72", "1.57188763"]], "a": [["65000.86", "2.61157325"]]}}
{"ts_ns": 1725000007600000000, "stream": "depth", "msg": {"e": "depthUpdate", "E": 1725000007600, "s": "BTCUSDT", "U": 1000199, "u": 1000200, "pu": 1000198, "b": [["65000.53", "1.89967400"], ["65000.53", "1.52985619"]], "a": [["65000.77", "2.32868469"]]}}
{"ts_ns": 1725000007644314944, "stream": "trade", "msg": {"e": "trade", "E": 1725000007600, "s": "BTCUSDT", "t": 10000024, "p": "65000.63", "q": "0.11889816", "m": true, "M": true, "T": 1725000007590}}
{"ts_ns": 1725000007700000000, "stream": "depth", "msg": {"e": "depthUpdate", "E": 1725000007700, "s": "BTCUSDT", "U": 1000201, "u": 1000203, "pu": 1000200, "b": [["65000.19", "2.27745714"], ["65000.30", "0.53143839"], ["65000.19", "1.88384632"], ["65000.24", "2.26333748"], ["65000.19", "1.73840427"]], "a": [["65000.43", "2.77246278"], ["65000.42", "1.92897549"]]}}
{"ts_ns": 1725000007800000000, "stream": "depth", "msg": {"e": "depthUpdate", "E": 1725000007800, "s": "BTCUSDT", "U": 1000204, "u": 1000206, "pu": 1000203, "b": [["65000.65", "1.31928845"], ["65000.60", "1.32662419"], ["65000.63", "2.38898904"], ["65000.58", "0.16851636"], ["65000.59", "0.22257197"], ["65000.60", "1.35574159"]], "a": [["65000.69", "1.10621280"], ["65000.73", "0.23019300"], ["65000.82", "2.93210560"]]}}
{"ts_ns": 1725000007840868021, "stream": "trade", "msg": {"e": "trade", "E": 1725000007800, "s": "BTCUSDT", "t": 10000025, "p": "65000.68", "q": "0.23189312", "m": true, "M": true, "T": 1725000007790}}
{"ts_ns": 1725000007900000000, "stream": "depth", "msg": {"e": "depthUpdate", "E": 1725000007900, "s": "BTCUSDT", "U": 1000207, "u": 1000210, "pu": 1000206, "b": [["65001.05", "0.96458029"], ["65001.01", "1.50410191"], ["65001.08", "1.35156933"], ["65000.96", "2.69738050"], ["65001.03", "2.94715674"]], "a": [["65001.11", "1.51364700"], ["65001.12", "0.11742638"], ["65001.21", "1.31327482"], ["65001.17", "1.57220566"], ["65001.19", "0.47623862"], ["65001.15", "2.75381037"]]}}
{"ts_ns": 1725000007923707434, "stream": "trade", "msg": {"e": "trade", "E": 1725000007900, "s": "BTCUSDT", "t": 10000026, "p": "65001.09", "q": "0.02713039", "m": false, "M": true, "T": 1725000007890}}
{"ts_ns": 1725000008000000000, "stream": "depth", "msg": {"e": "depthUpdate", "E": 1725000008000, "s": "BTCUSDT", "U": 1000211, "u": 1000211, "pu": 1000210, "b": [["65000.85", "0.85244092"], ["65000.80", "2.55469878"], ["65000.77", "1.80810244"], ["65000.89", "1.00008611"], ["65000.82", "1.99083632"]], "a": [["65001.07", "1.04946236"], ["65001.03", "2.09543989"], ["65000.99", "0.38685497"], ["65001.04", "2.81400660"], ["65000.97", "1.67676621"], ["65001.03", "2.37498587"]]}}
{"ts_ns": 1725000008100000000, "stream": "depth", "msg": {"e": "depthUpdate", "E": 1725000008100, "s": "BTCUSDT", "U": 1000212, "u": 1000216, "pu": 1000211, "b": [["65000.42", "1.08548429"], ["65000.45", "0.92659821"], ["65000.47", "1.02519704"], ["65000.38", "1.45881276"], ["65000.47", "2.99992986"], ["65000.48", "0.23149525"]], "a": [["65000.65", "2.36436052"], ["65000.60", "2.31262416"], ["65000.65", "2.21593201"], ["65000.60", "0.11324248"]]}}
{"ts_ns": 1725000008142475389, "stream": "trade", "msg": {"e": "trade", "E": 1725000008100, "s": "BTCUSDT", "t": 10000027, "p": "65000.50", "q": "0.18898322", "m": true, "M": true, "T": 1725000008090}}
{"ts_ns": 1725000008200000000, "stream": "depth", "msg": {"e": "depthUpdate", "E": 1725000008200, "s": "BTCUSDT", "U": 1000217, "u": 1000218, "pu": 1000216, "b": [["65000.72", "1.31302022"], ["65000.77", "1.09289824"], ["65000.72", "0.71259060"], ["65000.76", "1.83178627"], ["65000.71", "2.24560955"]], "a": [["65000.92", "0.70200883"], ["65000.88", "0.92840369"]]}}
{"ts_ns": 1725000008300000000, "stream": "depth", "msg": {"e": "depthUpdate", "E": 1725000008300, "s": "BTCUSDT", "U": 1000219, "u": 1000222, "pu": 1000218, "b": [["65001.13", "2.84139051"], ["65001.16", "1.38503994"]], "a": [["65001.29", "2.33437211"], ["65001.33", "1.58237937"], ["65001.27", "2.45067372"]]}}
{"ts_ns": 1725000008400000000, "stream": "depth", "msg": {"e": "depthUpdate", "E": 1725000008400, "s": "BTCUSDT", "U": 1000223, "u": 1000224, "pu": 1000222, "b": [["65001.53", "2.62235084"]], "a": [["65001.70", "2.80288066"], ["65001.73", "2.53767683"], ["65001.75", "0.37403332"], ["65001.63", "2.28935049"], ["65001.66", "1.34795766"], ["65001.70", "0.44204597"]]}}
{"ts_ns": 1725000008500000000, "stream": "depth", "msg": {"e": "depthUpdate", "E": 1725000008500, "s": "BTCUSDT", "U": 1000225, "u": 1000226, "pu": 1000224, "b": [["65001.86", "0.15977066"], ["65001.84", "1.12188446"], ["65001.86", "2.98357605"]], "a": [["65001.99", "0.67361628"]]}}
{"ts_ns": 1725000008507649355, "stream": "trade", "msg": {"e": "trade", "E": 1725000008500, "s": "BTCUSDT", "t": 10000028, "p": "65001.94", "q": "0.32533038", "m": true, "M": true, "T": 1725000008490}}
{"ts_ns": 1725000008600000000, "stream": "depth", "msg": {"e": "depthUpdate", "E": 1725000008600, "s": "BTCUSDT", "U": 1000227, "u": 1000228, "pu": 1000226, "b": [["65001.33", "0.41637808"], ["65001.35", "1.40733038"], ["65001.37", "0.01575359"], ["65001.45", "0.05701165"]], "a": [["65001.51", "2.50488930"], ["65001.56", "2.82067785"], ["65001.57", "1.58331452"], ["65001.49", "2.32851790"], ["65001.51", "0.90345358"], ["65001.48", "0.71531851"]]}}
{"ts_ns": 1725000008700000000, "stream": "depth", "msg": {"e": "depthUpdate", "E": 1725000008700, "s": "BTCUSDT", "U": 1000229, "u": 1000233, "pu": 1000228, "b": [["65001.33", "1.60816135"]], "a": [["65001.54", "1.54612719"], ["65001.47", "2.15563298"], ["65001.48", "1.28771668"], ["65001.53", "1.05844812"]]}}
{"ts_ns": 1725000008800000000, "stream": "depth", "msg": {"e": "depthUpdate", "E": 1725000008800, "s": "BTCUSDT", "U": 1000234, "u": 1000235, "pu": 1000233, "b": [["65001.53", "0.20303797"]], "a": [["65001.68", "1.63224588"], ["65001.72", "2.96499446"], ["65001.68", "0.06100292"], ["65001.73", "1.41040523"], ["65001.70", "1.16064396"]]}}
{"ts_ns": 1725000008802089997, "stream": "trade", "msg": {"e": "trade", "E": 1725000008800, "s": "BTCUSDT", "t": 10000029, "p": "65001.59", "q": "0.03471222", "m": true, "M": true, "T": 1725000008790}}
{"ts_ns": 1725000008900000000, "stream": "depth", "msg": {"e": "depthUpdate", "E": 1725000008900, "s": "BTCUSDT", "U": 1000236, "u": 1000236, "pu": 1000235, "b": [["65001.83", "0.13300706"], ["65001.77", "1.01564177"], ["65001.75", "0.52526738"], ["65001.73", "2.05404770"], ["65001.74", "1.43559351"], ["65001.83", "2.43449305"]], "a": [["65001.88", "2.14813517"], ["65001.94", "0.11095137"], ["65001.90", "0.13141883"]]}}
{"ts_ns": 1725000008903812260, "stream": "trade", "msg": {"e": "trade", "E": 1725000008900, "s": "BTCUSDT", "t": 10000030, "p": "65001.86", "q": "0.15572787", "m": false, "M": true, "T": 1725000008890}}
{"ts_ns": 1725000009000000000, "stream": "depth", "msg": {"e": "depthUpdate", "E": 1725000009000, "s": "BTCUSDT", "U": 1000237, "u": 1000241, "pu": 1000236, "b": [["65001.79", "0.85833269"]], "a": [["65001.97", "2.34252470"], ["65001.97", "1.96719410"], ["65001.88", "0.37342502"], ["65001.89", "1.31085415"], ["65001.90", "2.22992312"], ["65001.98", "2.86943615"]]}}
{"ts_ns": 1725000009013537091, "stream": "trade", "msg": {"e": "trade", "E": 1725000009000, "s": "BTCUSDT", "t": 10000031, "p": "65001.83", "q": "0.24926417", "m": false, "M": true, "T": 1725000008990}}
{"ts_ns": 1725000009100000000, "stream": "depth", "msg": {"e": "depthUpdate", "E": 1725000009100, "s": "BTCUSDT", "U": 1000242, "u": 1000242, "pu": 1000241, "b": [["65001.96", "2.98529449"]], "a": [["65002.09", "1.63642319"], ["65002.12", "0.30779372"], ["65002.12", "1.98275766"], ["65002.11", "1.33774729"]]}}
{"ts_ns": 1725000009200000000, "stream": "depth", "msg": {"e": "depthUpdate", "E": 1725000009200, "s": "BTCUSDT", "U": 1000243, "u": 1000244, "pu": 1000242, "b": [["65002.24", "2.18044319"], ["65002.10", "1.05767793"], ["65002.18", "0.82366608"]], "a": [["65002.38", "2.84371314"], ["65002.27", "2.01355167"], ["65002.32", "1.08993339"], ["65002.38", "2.24969395"]]}}
{"ts_ns": 1725000009203089811, "stream": "trade", "msg": {"e": "trade", "E": 1725000009200, "s": "BTCUSDT", "t": 10000032, "p": "65002.24", "q": "0.30417888", "m": false, "M": true, "T": 1725000009190}}
{"ts_ns": 1725000009300000000, "stream": "depth", "msg": {"e": "depthUpdate", "E": 1725000009300, "s": "BTCUSDT", "U": 1000245, "u": 1000245, "pu": 1000244, "b": [["65001.82", "1.08645175"], ["65001.78", "0.09715597"]], "a": [["65001.91", "2.03718617"], ["65001.94", "1.11604014"], ["65002.01", "0.23065629"], ["65001.91", "1.58837964"], ["65001.95", "0.94315632"], ["65001.93", "0.74883496"]]}}
{"ts_ns": 1725000009313485473, "stream": "trade", "msg": {"e": "trade", "E": 1725000009300, "s": "BTCUSDT", "t": 10000033, "p": "65001.88", "q": "0.19410670", "m": true, "M": true, "T": 1725000009290}}
{"ts_ns": 1725000009400000000, "stream": "depth", "msg": {"e": "depthUpdate", "E": 1725000009400, "s": "BTCUSDT", "U": 1000246, "u": 1000248, "pu": 1000245, "b": [["65002.11", "2.98909534"], ["65002.10", "2.08194192"], ["65002.07", "0.60053502"], ["65002.12", "2.55847887"], ["65002.07", "0.51796909"], ["65002.03", "1.33533358"]], "a": [["65002.17", "2.43153966"], ["65002.29", "2.95972398"], ["65002.26", "1.04227588"], ["65002.17", "1.64999144"]]}}
{"ts_ns": 1725000009421129751, "stream": "trade", "msg": {"e": "trade", "E": 1725000009400, "s": "BTCUSDT", "t": 10000034, "p": "65002.16", "q": "0.35619274", "m": true, "M": true, "T": 1725000009390}}
{"ts_ns": 1725000009500000000, "stream": "depth", "msg": {"e": "depthUpdate", "E": 1725000009500, "s": "BTCUSDT", "U": 1000249, "u": 1000251, "pu": 1000248, "b": [["65002.03", "0.41663062"]], "a": [["65002.29", "1.48206581"], ["65002.22", "1.66206431"]]}}
{"ts_ns": 1725000009538020399, "stream": "trade", "msg": {"e": "trade", "E": 1725000009500, "s": "BTCUSDT", "t": 10000035, "p": "65002.15", "q": "0.44223898", "m": true, "M": true, "T": 1725000009490}}
{"ts_ns": 1725000009600000000, "stream": "depth", "msg": {"e": "depthUpdate", "E": 1725000009600, "s": "BTCUSDT", "U": 1000252, "u": 1000254, "pu": 1000251, "b": [["65001.98", "1.57708696"], ["65001.93", "1.22830058"], ["65001.96", "0.22125214"], ["65002.00", "1.92701577"], ["65001.98", "1.39749960"], ["65001.97", "1.03354434"]], "a": [["65002.21", "2.48716118"], ["65002.15", "1.91938179"], ["65002.09", "2.30334491"], ["65002.09", "1.29785486"], ["65002.21", "2.60463488"], ["65002.20", "0.37248336"]]}}
{"ts_ns": 1725000009612049949, "stream": "trade", "msg": {"e": "trade", "E": 1725000009600, "s": "BTCUSDT", "t": 10000036, "p": "65002.05", "q": "0.46743418", "m": true, "M": true, "T": 1725000009590}}
{"ts_ns": 1725000009700000000, "stream": "depth", "msg": {"e": "depthUpdate", "E": 1725000009700, "s": "BTCUSDT", "U": 1000255, "u": 1000257, "pu": 1000254, "b": [["65002.37", "0.23657971"], ["65002.47", "1.90517127"], ["65002.42", "0.82335310"], ["65002.40", "0.90847382"], ["65002.42", "0.28028522"]], "a": [["65002.62", "0.50590771"], ["65002.61", "0.46258280"], ["65002.62", "1.87343756"]]}}
{"ts_ns": 1725000009800000000, "stream": "depth", "msg": {"e": "depthUpdate", "E": 1725000009800, "s": "BTCUSDT", "U": 1000258, "u": 1000260, "pu": 1000257, "b": [["65002.71", "2.59134357"], ["65002.83", "0.13638541"], ["65002.74", "2.31306711"], ["65002.80", "1.95338993"], ["65002.72", "1.71641161"]], "a": [["65002.95", "1.91697358"]]}}
{"ts_ns": 1725000009900000000, "stream": "depth", "msg": {"e": "depthUpdate", "E": 1725000009900, "s": "BTCUSDT", "U": 1000261, "u": 1000265, "pu": 1000260, "b": [["65002.60", "2.41406446"], ["65002.53", "1.21827758"], ["65002.56", "0.21891908"]], "a": [["65002.65", "0.47424134"], ["65002.71", "1.45275339"], ["65002.68", "1.02057771"], ["65002.67", "0.93774750"]]}}
{"ts_ns": 1725000010000000000, "stream": "depth", "msg": {"e": "depthUpdate", "E": 1725000010000, "s": "BTCUSDT", "U": 1000266, "u": 1000268, "pu": 1000265, "b": [["65003.03", "1.68495365"], ["65003.06", "0.72521358"]], "a": [["65003.14", "0.80241502"], ["65003.16", "0.42263291"], ["65003.13", "0.87063601"]]}}
{"ts_ns": 1725000010042297281, "stream": "trade", "msg": {"e": "trade", "E": 1725000010000, "s": "BTCUSDT", "t": 10000037, "p": "65003.12", "q": "0.48138024", "m": true, "M": true, "T": 1725000009990}}
{"ts_ns": 1725000010100000000, "stream": "depth", "msg": {"e": "depthUpdate", "E": 1725000010100, "s": "BTCUSDT", "U": 1000269, "u": 1000271, "pu": 1000268, "b": [["65003.51", "2.28936413"], ["65003.47", "2.98790823"], ["65003.47", "1.49627913"], ["65003.50", "1.49211082"], ["65003.53", "2.83569841"], ["65003.46", "1.37169193"]], "a": [["65003.59", "0.64543327"], ["65003.61", "0.14597440"], ["65003.60", "1.48468261"]]}}
{"ts_ns": 1725000010200000000, "stream": "depth", "msg": {"e": "depthUpdate", "E": 1725000010200, "s": "BTCUSDT", "U": 1000272, "u": 1000275, "pu": 1000271, "b": [["65003.27", "0.40180483"]], "a": [["65003.39", "2.18252419"]]}}
{"ts_ns": 1725000010300000000, "stream": "depth", "msg": {"e": "depthUpdate", "E": 1725000010300, "s": "BTCUSDT", "U": 1000276, "u": 1000278, "pu": 1000275, "b": [["65002.80", "0.58396591"]], "a": [["65002.98", "0.86580509"], ["65002.96", "1.51276659"], ["65003.02", "1.64957127"], ["65003.03", "2.96727210"], ["65003.00", "1.83312942"]]}}
{"ts_ns": 1725000010307488184, "stream": "trade", "msg": {"e": "trade", "E": 1725000010300, "s": "BTCUSDT", "t": 10000038, "p": "65002.89", "q": "0.39765372", "m": false, "M": true, "T": 1725000010290}}
{"ts_ns": 1725000010400000000, "stream": "depth", "msg": {"e": "depthUpdate", "E": 1725000010400, "s": "BTCUSDT", "U": 1000279, "u": 1000283, "pu": 1000278, "b": [["65003.23", "1.52736755"], ["65003.24", "0.12076472"]], "a": [["65003.34", "0.41110912"], ["65003.39", "2.41189757"]]}}
{"ts_ns": 1725000010500000000, "stream": "depth", "msg": {"e": "depthUpdate", "E": 1725000010500, "s": "BTCUSDT", "U": 1000284, "u": 1000285, "pu": 1000283, "b": [["65003.38", "2.79410621"], ["65003.38", "0.48750614"], ["65003.34", "2.21795808"], ["65003.39", "1.78117397"], ["65003.35", "2.48486816"]], "a": [["65003.53", "1.46953996"], ["65003.54", "0.89937169"]]}}
{"ts_ns": 1725000010600000000, "stream": "depth", "msg": {"e": "depthUpdate", "E": 1725000010600, "s": "BTCUSDT", "U": 1000286, "u": 1000288, "pu": 1000285, "b": [["65003.17", "0.92303350"]], "a": [["65003.42", "2.17597264"], ["65003.39", "1.88778144"], ["65003.37", "1.42377064"], ["65003.38", "2.34871197"]]}}
{"ts_ns": 1725000010700000000, "stream": "depth", "msg": {"e": "depthUpdate", "E": 1725000010700, "s": "BTCUSDT", "U": 1000289, "u": 1000293, "pu": 1000288, "b": [["65002.92", "0.51153619"]], "a": [["65003.11", "2.16354851"], ["65003.13", "2.52350137"], ["65003.03", "2.46498387"], ["65003.04", "0.09471154"], ["65003.12", "0.32968656"]]}}
{"ts_ns": 1725000010722051546, "stream": "trade", "msg": {"e": "trade", "E": 1725000010700, "s": "BTCUSDT", "t": 10000039, "p": "65003.00", "q": "0.20706709", "m": true, "M": true, "T": 1725000010690}}
{"ts_ns": 1725000010800000000, "stream": "depth", "msg": {"e": "depthUpdate", "E": 1725000010800, "s": "BTCUSDT", "U": 1000294, "u": 1000297, "pu": 1000293, "b": [["65002.86", "2.54513098"], ["65002.88", "0.18684386"], ["65002.97", "1.55604963"], ["65002.91", "0.97514860"], ["65002.89", "1.43511295"]], "a": [["65003.07", "0.94125780"], ["65003.03", "1.37899060"], ["65003.09", "1.02698105"], ["65003.06", "2.02760573"]]}}
{"ts_ns": 1725000010900000000, "stream": "depth", "msg": {"e": "depthUpdate", "E": 1725000010900, "s": "BTCUSDT", "U": 1000298, "u": 1000300, "pu": 1000297, "b": [["65003.06", "1.67425995"], ["65003.07", "2.82445664"]], "a": [["65003.16", "2.31352281"], ["65003.23", "0.62183338"]]}}
{"ts_ns": 1725000011000000000, "stream": "depth", "msg": {"e": "depthUpdate", "E": 1725000011000, "s": "BTCUSDT", "U": 1000301, "u": 1000303, "pu": 1000300, "b": [["65003.04", "0.86336813"], ["65002.99", "2.02986674"], ["65003.02", "2.68728138"], ["65003.02", "2.45513238"], ["65002.96", "2.41384750"]], "a": [["65003.14", "0.12619946"], ["65003.21", "0.23708831"], ["65003.24", "1.32712834"], ["65003.14", "2.24201550"], ["65003.13", "0.60620402"], ["65003.18", "0.81339817"]]}}
{"ts_ns": 1725000011100000000, "stream": "depth", "msg": {"e": "depthUpdate", "E": 1725000011100, "s": "BTCUSDT", "U": 1000304, "u": 1000306, "pu": 1000303, "b": [["65002.63", "0.71784620"], ["65002.72", "2.00950189"], ["65002.64", "0.67701494"], ["65002.69", "0.15747332"], ["65002.66", "0.99088087"]], "a": [["65002.81", "0.30163471"], ["65002.86", "0.41240110"], ["65002.82", "2.93373214"], ["65002.76", "1.22072235"], ["65002.88", "2.64194237"], ["65002.81", "1.43234556"]]}}
{"ts_ns": 1725000011120276688, "stream": "trade", "msg": {"e": "trade", "E": 1725000011100, "s": "BTCUSDT", "t": 10000040, "p": "65002.73", "q": "0.32330306", "m": true, "M": true, "T": 1725000011090}}
{"ts_ns": 1725000011200000000, "stream": "depth", "msg": {"e": "depthUpdate", "E": 1725000011200, "s": "BTCUSDT", "U": 1000307, "u": 1000311, "pu": 1000306, "b": [["65002.32", "2.81000814"], ["65002.31", "2.76441265"], ["65002.39", "2.64673492"], ["65002.43", "2.80176783"], ["65002.45", "2.99151541"], ["65002.39", "2.36388189"]], "a": [["65002.49", "2.80982623"], ["65002.60", "2.77811909"], ["65002.61", "0.11239853"], ["65002.51", "1.70388561"], ["65002.48", "2.78536454"], ["65002.52", "0.85368496"]]}}
{"ts_ns": 1725000011300000000, "stream": "depth", "msg": {"e": "depthUpdate", "E": 1725000011300, "s": "BTCUSDT", "U": 1000312, "u": 1000316, "pu": 1000311, "b": [["65002.40", "0.81851124"], ["65002.35", "0.33794028"]], "a": [["65002.51", "2.19335770"], ["65002.59", "0.77179464"], ["65002.51", "0.04225259"], ["65002.54", "2.37230299"], ["65002.58", "2.02320342"]]}}
{"ts_ns": 1725000011342000462, "stream": "trade", "msg": {"e": "trade", "E": 1725000011300, "s": "BTCUSDT", "t": 10000041, "p": "65002.49", "q": "0.44862434", "m": false, "M": true, "T": 1725000011290}}
{"ts_ns": 1725000011400000000, "stream": "depth", "msg": {"e": "depthUpdate", "E": 1725000011400, "s": "BTCUSDT", "U": 1000317, "u": 1000321, "pu": 1000316, "b": [["65002.29", "0.55434360"], ["65002.28", "1.43236230"], ["65002.16", "0.74414125"], ["65002.26", "1.15072317"]], "a": [["65002.39", "2.26126996"], ["65002.37", "0.90583752"], ["65002.43", "1.71863204"], ["65002.36", "1.96105010"], ["65002.43", "0.70890773"], ["65002.42", "0.35467454"]]}}
{"ts_ns": 1725000011428207048, "stream": "trade", "msg": {"e": "trade", "E": 1725000011400, "s": "BTCUSDT", "t": 10000042, "p": "65002.31", "q": "0.46162990", "m": false, "M": true, "T": 1725000011390}}
{"ts_ns": 1725000011500000000, "stream": "depth", "msg": {"e": "depthUpdate", "E": 1725000011500, "s": "BTCUSDT", "U": 1000322, "u": 1000322, "pu": 1000321, "b": [["65002.35", "0.66254772"], ["65002.42", "1.43454570"], ["65002.37", "2.24320451"]], "a": [["65002.55", "1.12087453"], ["65002.57", "1.64770353"], ["65002.53", "2.27205157"]]}}
{"ts_ns": 1725000011600000000, "stream": "depth", "msg": {"e": "depthUpdate", "E": 1725000011600, "s": "BTCUSDT", "U": 1000323, "u": 1000324, "pu": 1000322, "b": [["65002.57", "2.36211207"], ["65002.62", "1.34024393"], ["65002.59", "1.08535461"], ["65002.56", "1.69250617"], ["65002.70", "2.48632216"], ["65002.56", "1.51646117"]], "a": [["65002.81", "1.60998047"], ["65002.74", "0.98435291"], ["65002.80", "1.32552166"], ["65002.82", "0.61620446"], ["65002.81", "1.46648390"]]}}
{"ts_ns": 1725000011700000000, "stream": "depth", "msg": {"e": "depthUpdate", "E": 1725000011700, "s": "BTCUSDT", "U": 1000325, "u": 1000328, "pu": 1000324, "b": [["65002.93", "1.24627372"], ["65002.92", "0.17321034"], ["65002.94", "2.01830314"], ["65002.97", "2.16984024"]], "a": [["65003.09", "0.76337166"], ["65003.03", "2.23741345"]]}}
{"ts_ns": 1725000011800000000, "stream": "depth", "msg": {"e": "depthUpdate", "E": 1725000011800, "s": "BTCUSDT", "U": 1000329, "u": 1000329, "pu": 1000328, "b": [["65002.85", "2.98237098"], ["65002.79", "2.68265534"], ["65002.79", "1.41621360"], ["65002.89", "1.22660081"], ["65002.81", "0.40628660"], ["65002.83", "2.93499985"]], "a": [["65003.05", "2.89134770"]]}}
{"ts_ns": 1725000011826667772, "stream": "trade", "msg": {"e": "trade", "E": 1725000011800, "s": "BTCUSDT", "t": 10000043, "p": "65002.94", "q": "0.45864042", "m": false, "M": true, "T": 1725000011790}}
{"ts_ns": 1725000011900000000, "stream": "depth", "msg": {"e": "depthUpdate", "E": 1725000011900, "s": "BTCUSDT", "U": 1000330, "u": 1000333, "pu": 1000329, "b": [["65002.49", "1.96060230"], ["65002.46", "0.35589950"], ["65002.43", "1.17917590"], ["65002.49", "2.18357442"], ["65002.48", "2.50446484"], ["65002.39", "0.06820598"]], "a": [["65002.57", "1.38901170"], ["65002.64", "1.63333602"], ["65002.61", "1.13782940"], ["65002.56", "0.74253612"], ["65002.58", "0.46536412"]]}}
{"ts_ns": 1725000011949655533, "stream": "trade", "msg": {"e": "trade", "E": 1725000011900, "s": "BTCUSDT", "t": 10000044, "p": "65002.53", "q": "0.01707644", "m": false, "M": true, "T": 1725000011890}}
{"ts_ns": 1725000012000000000, "stream": "depth", "msg": {"e": "depthUpdate", "E": 1725000012000, "s": "BTCUSDT", "U": 1000334, "u": 1000338, "pu": 1000333, "b": [["65002.75", "0.20187271"]], "a": [["65002.89", "0.10072883"], ["65002.89", "2.01607091"]]}}
{"ts_ns": 1725000012100000000, "stream": "depth", "msg": {"e": "depthUpdate", "E": 1725000012100, "s": "BTCUSDT", "U": 1000339, "u": 1000340, "pu": 1000338, "b": [["65002.99", "1.61927943"], ["65002.90", "2.59119073"], ["65003.02", "0.42040673"], ["65002.98", "0.70248455"]], "a": [["65003.18", "2.19455245"], ["65003.09", "1.73242444"], ["65003.16", "2.01759570"], ["65003.09", "0.71071210"]]}}
{"ts_ns": 1725000012200000000, "stream": "depth", "msg": {"e": "depthUpdate", "E": 1725000012200, "s": "BTCUSDT", "U": 1000341, "u": 1000345, "pu": 1000340, "b": [["65002.74", "1.67015435"], ["65002.65", "2.63914167"], ["65002.60", "0.52539956"]], "a": [["65002.86", "1.28160175"], ["65002.83", "0.14065229"], ["65002.81", "2.82475923"]]}}
{"ts_ns": 1725000012300000000, "stream": "depth", "msg": {"e": "depthUpdate", "E": 1725000012300, "s": "BTCUSDT", "U": 1000346, "u": 1000350, "pu": 1000345, "b": [["65002.54", "0.89966548"], ["65002.54", "2.26324829"], ["65002.49", "0.72290457"], ["65002.53", "0.90220926"]], "a": [["65002.69", "0.43305525"], ["65002.65", "2.74422352"], ["65002.66", "1.23803247"], ["65002.64", "1.67186027"]]}}
{"ts_ns": 1725000012317297959, "stream": "trade", "msg": {"e": "trade", "E": 1725000012300, "s": "BTCUSDT", "t": 10000045, "p": "65002.57", "q": "0.16580123", "m": true, "M": true, "T": 1725000012290}}
{"ts_ns": 1725000012400000000, "stream": "depth", "msg": {"e": "depthUpdate", "E": 1725000012400, "s": "BTCUSDT", "U": 1000351, "u": 1000354, "pu": 1000350, "b": [["65002.80", "2.48821886"]], "a": [["65002.93", "0.80538476"], ["65003.03", "1.81490834"], ["65002.93", "2.62086138"], ["65002.96", "2.41395185"], ["65003.02", "2.17291572"]]}}
{"ts_ns": 1725000012500000000, "stream": "depth", "msg": {"e": "depthUpdate", "E": 1725000012500, "s": "BTCUSDT", "U": 1000355, "u": 1000358, "pu": 1000354, "b": [["65002.48", "0.04600112"], ["65002.48", "0.57007109"], ["65002.51", "0.35194860"]], "a": [["65002.76", "1.43676263"], ["65002.67", "2.08687886"], ["65002.75", "0.61353943"]]}}
{"ts_ns": 1725000012600000000, "stream": "depth", "msg": {"e": "depthUpdate", "E": 1725000012600, "s": "BTCUSDT", "U": 1000359, "u": 1000363, "pu": 1000358, "b": [["65002.37", "1.60095038"], ["65002.39", "0.92526685"], ["65002.39", "1.53844962"]], "a": [["65002.53", "1.39801220"], ["65002.58", "2.94395537"], ["65002.53", "2.28488691"], ["65002.51", "2.74299150"]]}}
{"ts_ns": 1725000012628778383, "stream": "trade", "msg": {"e": "trade", "E": 1725000012600, "s": "BTCUSDT", "t": 10000046, "p": "65002.44", "q": "0.43217834", "m": true, "M": true, "T": 1725000012590}}
{"ts_ns": 1725000012700000000, "stream": "depth", "msg": {"e": "depthUpdate", "E": 1725000012700, "s": "BTCUSDT", "U": 1000364, "u": 1000364, "pu": 1000363, "b": [["65002.09", "1.25273422"], ["65002.18", "0.58857535"], ["65002.17", "1.13951932"], ["65002.07", "0.73719005"], ["65002.12", "1.96382390"]], "a": [["65002.32", "1.01269285"], ["65002.34", "2.46477582"], ["65002.33", "1.92508336"], ["65002.29", "1.38248700"], ["65002.33", "2.38492654"]]}}
{"ts_ns": 1725000012749339422, "stream": "trade", "msg": {"e": "trade", "E": 1725000012700, "s": "BTCUSDT", "t": 10000047, "p": "65002.21", "q": "0.09283984", "m": true, "M": true, "T": 1725000012690}}
{"ts_ns": 1725000012800000000, "stream": "depth", "msg": {"e": "depthUpdate", "E": 1725000012800, "s": "BTCUSDT", "U": 1000365, "u": 1000369, "pu": 1000364, "b": [["65001.73", "2.29301653"]], "a": [["65001.81", "0.41247459"], ["65001.85", "0.69430018"], ["65001.86", "0.45308894"], ["65001.78", "1.51719876"], ["65001.80", "0.18135036"], ["65001.85", "2.00026419"]]}}
{"ts_ns": 1725000012900000000, "stream": "depth", "msg": {"e": "depthUpdate", "E": 1725000012900, "s": "BTCUSDT", "U": 1000370, "u": 1000373, "pu": 1000369, "b": [["65001.81", "1.65493068"]], "a": [["65001.91", "0.05017844"]]}}
{"ts_ns": 1725000013000000000, "stream": "depth", "msg": {"e": "depthUpdate", "E": 1725000013000, "s": "BTCUSDT", "U": 1000374, "u": 1000378, "pu": 1000373, "b": [["65002.24", "2.09357723"]], "a": [["65002.45", "2.41850310"], ["65002.53", "0.53780052"], ["65002.53", "0.28894167"], ["65002.41", "0.72290650"], ["65002.48", "1.57936796"]]}}
{"ts_ns": 1725000013100000000, "stream": "depth", "msg": {"e": "depthUpdate", "E": 1725000013100, "s": "BTCUSDT", "U": 1000379, "u": 1000381, "pu": 1000378, "b": [["65002.60", "1.37699324"]], "a": [["65002.71", "2.97069909"], ["65002.71", "0.89992392"], ["65002.81", "2.54360131"]]}}
{"ts_ns": 1725000013200000000, "stream": "depth", "msg": {"e": "depthUpdate", "E": 1725000013200, "s": "BTCUSDT", "U": 1000382, "u": 1000382, "pu": 1000381, "b": [["65002.17", "1.42801530"], ["65002.15", "0.02835052"], ["65002.23", "0.24805837"], ["65002.12", "1.30172896"]], "a": [["65002.39", "0.99381185"], ["65002.40", "2.92151924"], ["65002.41", "1.58447756"], ["65002.27", "0.68929949"]]}}
{"ts_ns": 1725000013300000000, "stream": "depth", "msg": {"e": "depthUpdate", "E": 1725000013300, "s": "BTCUSDT", "U": 1000383, "u": 1000387, "pu": 1000382, "b": [["65002.13", "2.77675443"]], "a": [["65002.39", "1.62909209"]]}}
{"ts_ns": 1725000013400000000, "stream": "depth", "msg": {"e": "depthUpdate", "E": 1725000013400, "s": "BTCUSDT", "U": 1000388, "u": 1000389, "pu": 1000387, "b": [["65002.63", "1.76110831"], ["65002.54", "2.46207222"], ["65002.53", "1.19488806"]], "a": [["65002.69", "0.89783067"]]}}
{"ts_ns": 1725000013500000000, "stream": "depth", "msg": {"e": "depthUpdate", "E": 1725000013500, "s": "BTCUSDT", "U": 1000390, "u": 1000394, "pu": 1000389, "b": [["65002.85", "1.62168729"], ["65002.93", "2.26682779"], ["65002.97", "2.37149426"], ["65002.88", "2.17249071"]], "a": [["65003.09", "2.23636968"], ["65003.06", "0.16108930"], ["65003.07", "0.69643201"], ["65003.02", "1.02177824"], ["65003.13", "1.84159570"], ["65003.10", "1.19010915"]]}}
{"ts_ns": 1725000013600000000, "stream": "depth", "msg": {"e": "depthUpdate", "E": 1725000013600, "s": "BTCUSDT", "U": 1000395, "u": 1000395, "pu": 1000394, "b": [["65003.09", "1.06743359"], ["65003.06", "1.29554384"], ["65003.02", "1.75762536"], ["65003.06", "0.25708235"]], "a": [["65003.23", "0.88613844"], ["65003.17", "2.13932560"], ["65003.15", "0.80391609"], ["65003.20", "2.13503146"]]}}
{"ts_ns": 1725000013700000000, "stream": "depth", "msg": {"e": "depthUpdate", "E": 1725000013700, "s": "BTCUSDT", "U": 1000396, "u": 1000399, "pu": 1000395, "b": [["65002.94", "2.82888068"]], "a": [["65003.03", "1.07975249"]]}}
{"ts_ns": 1725000013709892394, "stream": "trade", "msg": {"e": "trade", "E": 1725000013700, "s": "BTCUSDT", "t": 10000048, "p": "65002.94", "q": "0.21605878", "m": false, "M": true, "T": 1725000013690}}
{"ts_ns": 1725000013800000000, "stream": "depth", "msg": {"e": "depthUpdate", "E": 1725000013800, "s": "BTCUSDT", "U": 1000400, "u": 1000400, "pu": 1000399, "b": [["65002.46", "1.79077367"], ["65002.35", "0.97329099"], ["65002.41", "0.03702184"]], "a": [["65002.55", "1.16339868"], ["65002.50", "2.17453153"], ["65002.57", "2.71562272"], ["65002.52", "1.71588129"], ["65002.51", "2.05594798"]]}}
{"ts_ns": 1725000013819046846, "stream": "trade", "msg": {"e": "trade", "E": 1725000013800, "s": "BTCUSDT", "t": 10000049, "p": "65002.48", "q": "0.24706885", "m": true, "M": true, "T": 1725000013790}}
{"ts_ns": 1725000013900000000, "stream": "depth", "msg": {"e": "depthUpdate", "E": 1725000013900, "s": "BTCUSDT", "U": 1000401, "u": 1000402, "pu": 1000400, "b": [["65002.33", "2.34799987"], ["65002.35", "0.75509921"], ["65002.37", "2.16269836"], ["65002.33", "1.78141919"]], "a": [["65002.45", "1.37358490"], ["65002.44", "0.91397399"], ["65002.48", "0.99665165"]]}}
{"ts_ns": 1725000014000000000, "stream": "depth", "msg": {"e": "depthUpdate", "E": 1725000014000, "s": "BTCUSDT", "U": 1000403, "u": 1000405, "pu": 1000402, "b": [["65002.25", "0.40837341"], ["65002.29", "1.80963381"], ["65002.23", "0.60255447"], ["65002.29", "0.53291181"]], "a": [["65002.42", "2.90617567"], ["65002.40", "2.20462310"], ["65002.46", "1.47302194"], ["65002.45", "2.34592311"], ["65002.41", "1.12816591"], ["65002.49", "2.35759960"]]}}
{"ts_ns": 1725000014038839367, "stream": "trade", "msg": {"e": "trade", "E": 1725000014000, "s": "BTCUSDT", "t": 10000050, "p": "65002.34", "q": "0.49863520", "m": true, "M": true, "T": 1725000013990}}
{"ts_ns": 1725000014100000000, "stream": "depth", "msg": {"e": "depthUpdate", "E": 1725000014100, "s": "BTCUSDT", "U": 1000406, "u": 1000410, "pu": 1000405, "b": [["65001.76", "0.62894519"], ["65001.75", "0.87399362"], ["65001.76", "0.20747602"], ["65001.74", "2.38697051"], ["65001.81", "2.01893296"], ["65001.85", "1.90000812"]], "a": [["65001.92", "0.75804505"], ["65001.91", "2.14570917"], ["65002.01", "1.13097245"], ["65001.96", "2.97210184"]]}}
{"ts_ns": 1725000014200000000, "stream": "depth", "msg": {"e": "depthUpdate", "E": 1725000014200, "s": "BTCUSDT", "U": 1000411, "u": 1000414, "pu": 1000410, "b": [["65001.82", "0.11029549"], ["65001.85", "2.10490286"], ["65001.78", "1.61071796"], ["65001.80", "2.74320375"], ["65001.89", "2.30686214"], ["65001.80", "1.99408166"]], "a": [["65001.94", "1.94099954"], ["65001.92", "1.68966088"], ["65002.02", "2.03241569"], ["65001.98", "2.90043340"]]}}
{"ts_ns": 1725000014229887382, "stream": "trade", "msg": {"e": "trade", "E": 1725000014200, "s": "BTCUSDT", "t": 10000051, "p": "65001.90", "q": "0.05020467", "m": true, "M": true, "T": 1725000014190}}
{"ts_ns": 1725000014300000000, "stream": "depth", "msg": {"e": "depthUpdate", "E": 1725000014300, "s": "BTCUSDT", "U": 1000415, "u": 1000419, "pu": 1000414, "b": [["65002.04", "1.72570619"], ["65002.08", "1.12235870"], ["65002.08", "2.31702670"], ["65002.06", "2.07131192"], ["65002.13", "1.03490216"]], "a": [["65002.17", "1.44831325"], ["65002.21", "1.24792629"], ["65002.18", "0.34820801"], ["65002.28", "0.42502553"], ["65002.21", "1.02920004"]]}}
{"ts_ns": 1725000014400000000, "stream": "depth", "msg": {"e": "depthUpdate", "E": 1725000014400, "s": "BTCUSDT", "U": 1000420, "u": 1000424, "pu": 1000419, "b": [["65002.06", "2.16598183"], ["65002.06", "0.95672842"], ["65002.09", "0.13404916"], ["65002.02", "0.34525580"]], "a": [["65002.28", "1.02923384"]]}}
{"ts_ns": 1725000014412029616, "stream": "trade", "msg": {"e": "trade", "E": 1725000014400, "s": "BTCUSDT", "t": 10000052, "p": "65002.15", "q": "0.37050425", "m": true, "M": true, "T": 1725000014390}}
{"ts_ns": 1725000014500000000, "stream": "depth", "msg": {"e": "depthUpdate", "E": 1725000014500, "s": "BTCUSDT", "U": 1000425, "u": 1000429, "pu": 1000424, "b": [["65001.72", "0.69556664"], ["65001.73", "1.88928096"], ["65001.77", "1.92143663"], ["65001.73", "1.18674713"], ["65001.68", "1.84232081"]], "a": [["65001.84", "1.34872503"], ["65001.87", "1.16650734"], ["65001.92", "0.64438832"], ["65001.85", "2.25697649"]]}}
{"ts_ns": 1725000014600000000, "stream": "depth", "msg": {"e": "depthUpdate", "E": 1725000014600, "s": "BTCUSDT", "U": 1000430, "u": 1000430, "pu": 1000429, "b": [["65001.82", "0.97795473"], ["65001.80", "0.34186491"], ["65001.77", "2.58790964"], ["65001.79", "2.89774920"], ["65001.82", "1.79091249"]], "a": [["65001.98", "1.17763202"], ["65001.90", "1.04377391"]]}}
{"ts_ns": 1725000014700000000, "stream": "depth", "msg": {"e": "depthUpdate", "E": 1725000014700, "s": "BTCUSDT", "U": 1000431, "u": 1000435, "pu": 1000430, "b": [["65001.42", "0.89233450"], ["65001.45", "1.77050509"], ["65001.44", "0.40184331"], ["65001.53", "0.71571818"], ["65001.53", "0.54913355"], ["65001.43", "0.42407563"]], "a": [["65001.62", "1.25471732"], ["65001.58", "1.72441813"], ["65001.62", "0.55726110"], ["65001.66", "1.61213781"], ["65001.70", "1.93578029"], ["65001.58", "1.66473773"]]}}
{"ts_ns": 1725000014800000000, "stream": "depth", "msg": {"e": "depthUpdate", "E": 1725000014800, "s": "BTCUSDT", "U": 1000436, "u": 1000437, "pu": 1000435, "b": [["65001.23", "2.59656669"], ["65001.23", "1.45382676"], ["65001.20", "2.44564782"], ["65001.15", "1.51631406"]], "a": [["65001.32", "1.22740305"], ["65001.32", "1.24689131"], ["65001.38", "1.33155523"], ["65001.27", "0.24801188"], ["65001.25", "2.38764267"]]}}
{"ts_ns": 1725000014803194130, "stream": "trade", "msg": {"e": "trade", "E": 1725000014800, "s": "BTCUSDT", "t": 10000053, "p": "65001.24", "q": "0.26926670", "m": true, "M": true, "T": 1725000014790}}
{"ts_ns": 1725000014900000000, "stream": "depth", "msg": {"e": "depthUpdate", "E": 1725000014900, "s": "BTCUSDT", "U": 1000438, "u": 1000441, "pu": 1000437, "b": [["65001.22", "0.33963299"], ["65001.29", "0.80366673"], ["65001.22", "2.46984842"], ["65001.25", "1.62613014"]], "a": [["65001.44", "0.12483157"], ["65001.43", "1.32409974"], ["65001.35", "2.96932718"], ["65001.33", "2.20796609"], ["65001.42", "2.25403648"]]}}
{"ts_ns": 1725000014903162945, "stream": "trade", "msg": {"e": "trade", "E": 1725000014900, "s": "BTCUSDT", "t": 10000054, "p": "65001.31", "q": "0.17493991", "m": true, "M": true, "T": 1725000014890}}
{"ts_ns": 1725000015000000000, "stream": "depth", "msg": {"e": "depthUpdate", "E": 1725000015000, "s": "BTCUSDT", "U": 1000442, "u": 1000445, "pu": 1000441, "b": [["65001.64", "2.43210815"]], "a": [["65001.78", "2.06740076"], ["65001.82", "2.13226188"]]}}
{"ts_ns": 1725000015100000000, "stream": "depth", "msg": {"e": "depthUpdate", "E": 1725000015100, "s": "BTCUSDT", "U": 1000446, "u": 1000447, "pu": 1000445, "b": [["65001.67", "0.17807350"], ["65001.74", "1.59684239"]], "a": [["65001.90", "1.61630564"], ["65001.86", "2.93700047"]]}}
{"ts_ns": 1725000015139435634, "stream": "trade", "msg": {"e": "trade", "E": 1725000015100, "s": "BTCUSDT", "t": 10000055, "p": "65001.80", "q": "0.42915041", "m": true, "M": true, "T": 1725000015090}}
{"ts_ns": 1725000015200000000, "stream": "depth", "msg": {"e": "depthUpdate", "E": 1725000015200, "s": "BTCUSDT", "U": 1000448, "u": 1000449, "pu": 1000447, "b": [["65002.21", "2.60114277"], ["65002.23", "2.10427958"], ["65002.23", "0.74903173"], ["65002.14", "0.96629013"]], "a": [["65002.30", "2.28442076"]]}}
{"ts_ns": 1725000015300000000, "stream": "depth", "msg": {"e": "depthUpdate", "E": 1725000015300, "s": "BTCUSDT", "U": 1000450, "u": 1000453, "pu": 1000449, "b": [["65001.79", "1.24267527"], ["65001.82", "0.22654882"], ["65001.77", "2.64037524"], ["65001.88", "1.20855232"], ["65001.78", "0.83467706"], ["65001.75", "2.63195207"]], "a": [["65001.98", "2.85076224"], ["65001.96", "1.74586663"], ["65002.04", "2.32240587"]]}}
{"ts_ns": 1725000015400000000, "stream": "depth", "msg": {"e": "depthUpdate", "E": 1725000015400, "s": "BTCUSDT", "U": 1000454, "u": 1000457, "pu": 1000453, "b": [["65001.89", "0.18999206"], ["65001.94", "1.19314760"], ["65001.96", "2.47454294"], ["65001.95", "0.80561051"], ["65001.89", "0.85077923"], ["65001.94", "1.73380092"]], "a": [["65002.13", "2.55726773"], ["65002.16", "1.03121886"], ["65002.14", "2.28676207"]]}}
{"ts_ns": 1725000015443022196, "stream": "trade", "msg": {"e": "trade", "E": 1725000015400, "s": "BTCUSDT", "t": 10000056, "p": "65002.04", "q": "0.23033130", "m": true, "M": true, "T": 1725000015390}}
{"ts_ns": 1725000015500000000, "stream": "depth", "msg": {"e": "depthUpdate", "E": 1725000015500, "s": "BTCUSDT", "U": 1000458, "u": 1000459, "pu": 1000457, "b": [["65001.93", "2.98708221"]], "a": [["65002.12", "0.39573926"], ["65002.08", "0.90559651"], ["65002.11", "2.79817669"], ["65002.02", "0.28001995"]]}}
{"ts_ns": 1725000015506531148, "stream": "trade", "msg": {"e": "trade", "E": 1725000015500, "s": "BTCUSDT", "t": 10000057, "p": "65001.97", "q": "0.45199633", "m": true, "M": true, "T": 1725000015490}}
{"ts_ns": 1725000015600000000, "stream": "depth", "msg": {"e": "depthUpdate", "E": 1725000015600, "s": "BTCUSDT", "U": 1000460, "u": 1000460, "pu": 1000459, "b": [["65001.75", "2.26569647"], ["65001.80", "1.96645569"], ["65001.75", "0.28555103"]], "a": [["65001.91", "1.43042012"], ["65001.90", "1.78103849"], ["65001.96", "2.03994818"], ["65001.88", "0.02418771"], ["65001.93", "2.45132708"], ["65002.01", "1.26694180"]]}}
{"ts_ns": 1725000015605753207, "stream": "trade", "msg": {"e": "trade", "E": 1725000015600, "s": "BTCUSDT", "t": 10000058, "p": "65001.86", "q": "0.04557621", "m": true, "M": true, "T": 1725000015590}}
{"ts_ns": 1725000015700000000, "stream": "depth", "msg": {"e": "depthUpdate", "E": 1725000015700, "s": "BTCUSDT", "U": 1000461, "u": 1000461, "pu": 1000460, "b": [["65001.61", "2.32038145"], ["65001.55", "2.62349189"], ["65001.57", "2.97882047"]], "a": [["65001.71", "0.20523482"], ["65001.78", "0.02542423"]]}}
{"ts_ns": 1725000015800000000, "stream": "depth", "msg": {"e": "depthUpdate", "E": 1725000015800, "s": "BTCUSDT", "U": 1000462, "u": 1000465, "pu": 1000461, "b": [["65001.41", "0.45412239"], ["65001.46", "1.84822804"]], "a": [["65001.61", "2.57988757"], ["65001.55", "2.68977884"], ["65001.56", "2.25733694"], ["65001.63", "2.19002745"], ["65001.59", "2.88974613"], ["65001.59", "2.37322998"]]}}
{"ts_ns": 1725000015844259754, "stream": "trade", "msg": {"e": "trade", "E": 1725000015800, "s": "BTCUSDT", "t": 10000059, "p": "65001.52", "q": "0.27714492", "m": false, "M": true, "T": 1725000015790}}
{"ts_ns": 1725000015900000000, "stream": "depth", "msg": {"e": "depthUpdate", "E": 1725000015900, "s": "BTCUSDT", "U": 1000466, "u": 1000466, "pu": 1000465, "b": [["65001.84", "1.55324738"], ["65001.79", "0.56593957"], ["65001.81", "0.88662615"], ["65001.87", "2.35140480"], ["65001.75", "2.86401453"], ["65001.80", "1.15765672"]], "a": [["65001.92", "1.49874762"], ["65001.98", "0.21303601"], ["65002.03", "2.93309084"]]}}
{"ts_ns": 1725000016000000000, "stream": "depth", "msg": {"e": "depthUpdate", "E": 1725000016000, "s": "BTCUSDT", "U": 1000467, "u": 1000469, "pu": 1000466, "b": [["65001.45", "1.63906866"], ["65001.48", "2.28817781"], ["65001.38", "0.21897552"], ["65001.41", "0.20259771"], ["65001.46", "0.64722882"]], "a": [["65001.66", "0.18140658"], ["65001.64", "1.19392507"], ["65001.56", "1.88571209"], ["65001.60", "2.30133000"]]}}
{"ts_ns": 1725000016100000000, "stream": "depth", "msg": {"e": "depthUpdate", "E": 1725000016100, "s": "BTCUSDT", "U": 1000470, "u": 1000473, "pu": 1000469, "b": [["65000.99", "0.45804133"], ["65001.07", "0.92972066"], ["65001.00", "2.76277458"], ["65000.96", "0.46613139"], ["65001.03", "1.17219451"]], "a": [["65001.20", "2.28967239"], ["65001.20", "2.04316705"], ["65001.11", "0.93050848"], ["65001.16", "2.18987513"], ["65001.23", "0.71591216"]]}}
{"ts_ns": 1725000016130157700, "stream": "trade", "msg": {"e": "trade", "E": 1725000016100, "s": "BTCUSDT", "t": 10000060, "p": "65001.08", "q": "0.30653610", "m": true, "M": true, "T": 1725000016090}}
{"ts_ns": 1725000016200000000, "stream": "depth", "msg": {"e": "depthUpdate", "E": 1725000016200, "s": "BTCUSDT", "U": 1000474, "u": 1000476, "pu": 1000473, "b": [["65001.23", "0.35832902"], ["65001.14", "0.41163539"], ["65001.25", "0.49149789"], ["65001.20", "1.56901609"], ["65001.13", "2.46752062"], ["65001.21", "0.50088886"]], "a": [["65001.29", "2.24932915"], ["65001.40", "0.80629346"], ["65001.41", "0.35417016"], ["65001.41", "0.08806875"], ["65001.39", "1.28797371"], ["65001.35", "0.19161597"]]}}
{"ts_ns": 1725000016300000000, "stream": "depth", "msg": {"e": "depthUpdate", "E": 1725000016300, "s": "BTCUSDT", "U": 1000477, "u": 1000481, "pu": 1000476, "b": [["65001.30", "1.08037169"], ["65001.31", "2.57807935"], ["65001.36", "1.10306333"], ["65001.34", "2.31998686"]], "a": [["65001.54", "1.72173692"], ["65001.51", "0.34600081"], ["65001.51", "1.52647465"], ["65001.40", "2.57606703"]]}}
{"ts_ns": 1725000016304085768, "stream": "trade", "msg": {"e": "trade", "E": 1725000016300, "s": "BTCUSDT", "t": 10000061, "p": "65001.39", "q": "0.19210676", "m": true, "M": true, "T": 1725000016290}}
{"ts_ns": 1725000016400000000, "stream": "depth", "msg": {"e": "depthUpdate", "E": 1725000016400, "s": "BTCUSDT", "U": 1000482, "u": 1000483, "pu": 1000481, "b": [["65001.69", "2.74184301"]], "a": [["65001.94", "1.96710988"], ["65001.86", "0.96540604"], ["65001.89", "2.74756429"], ["65001.88", "0.81377387"], ["65001.84", "1.71460789"]]}}
{"ts_ns": 1725000016446186123, "stream": "trade", "msg": {"e": "trade", "E": 1725000016400, "s": "BTCUSDT", "t": 10000062, "p": "65001.83", "q": "0.09049283", "m": true, "M": true, "T": 1725000016390}}
{"ts_ns": 1725000016500000000, "stream": "depth", "msg": {"e": "depthUpdate", "E": 1725000016500, "s": "BTCUSDT", "U": 1000484, "u": 1000487, "pu": 1000483, "b": [["65001.26", "2.53453951"], ["65001.33", "0.25915657"], ["65001.31", "0.02390752"], ["65001.35", "0.87478527"]], "a": [["65001.52", "0.91172792"], ["65001.49", "0.72775198"], ["65001.45", "1.77507280"]]}}
{"ts_ns": 1725000016600000000, "stream": "depth", "msg": {"e": "depthUpdate", "E": 1725000016600, "s": "BTCUSDT", "U": 1000488, "u": 1000489, "pu": 1000487, "b": [["65001.59", "0.01913365"], ["65001.55", "0.07173077"], ["65001.53", "1.03927109"], ["65001.48", "2.08038242"], ["65001.61", "2.85297079"]], "a": [["65001.63", "2.27678746"], ["65001.69", "2.54701796"]]}}
{"ts_ns": 1725000016700000000, "stream": "depth", "msg": {"e": "depthUpdate", "E": 1725000016700, "s": "BTCUSDT", "U": 1000490, "u": 1000490, "pu": 1000489, "b": [["65001.25", "2.88355518"], ["65001.30", "2.13495742"]], "a": [["65001.35", "0.13170080"], ["65001.37", "2.69186242"], ["65001.42", "1.23917041"], ["65001.48", "1.11747592"]]}}
{"ts_ns": 1725000016800000000, "stream": "depth", "msg": {"e": "depthUpdate", "E": 1725000016800, "s": "BTCUSDT", "U": 1000491, "u": 1000491, "pu": 1000490, "b": [["65001.30", "2.45988868"], ["65001.39", "1.77568729"], ["65001.40", "1.30494864"], ["65001.38", "0.71031520"], ["65001.36", "2.55274112"]], "a": [["65001.56", "2.40245047"], ["65001.53", "2.49569950"]]}}
{"ts_ns": 1725000016831384065, "stream": "trade", "msg": {"e": "trade", "E": 1725000016800, "s": "BTCUSDT", "t": 10000063, "p": "65001.41", "q": "0.03826903", "m": true, "M": true, "T": 1725000016790}}
{"ts_ns": 1725000016900000000, "stream": "depth", "msg": {"e": "depthUpdate", "E": 1725000016900, "s": "BTCUSDT", "U": 1000492, "u": 1000493, "pu": 1000491, "b": [["65001.66", "0.31697325"], ["65001.61", "1.39816534"], ["65001.62", "0.36221021"], ["65001.63", "2.89390417"], ["65001.65", "1.35575123"]], "a": [["65001.77", "0.79502378"]]}}
{"ts_ns": 1725000016911577388, "stream": "trade", "msg": {"e": "trade", "E": 1725000016900, "s": "BTCUSDT", "t": 10000064, "p": "65001.70", "q": "0.15280328", "m": true, "M": true, "T": 1725000016890}}
{"ts_ns": 1725000017000000000, "stream": "depth", "msg": {"e": "depthUpdate", "E": 1725000017000, "s": "BTCUSDT", "U": 1000494, "u": 1000495, "pu": 1000493, "b": [["65002.01", "2.13347219"], ["65001.97", "1.18873339"], ["65002.02", "2.03155013"]], "a": [["65002.08", "2.46026885"], ["65002.06", "0.09324628"]]}}
{"ts_ns": 1725000017100000000, "stream": "depth", "msg": {"e": "depthUpdate", "E": 1725000017100, "s": "BTCUSDT", "U": 1000496, "u": 1000499, "pu": 1000495, "b": [["65002.07", "1.38612975"], ["65001.96", "2.38142923"], ["65002.07", "0.03587077"], ["65001.95", "2.34287998"], ["65002.05", "0.39214571"]], "a": [["65002.23", "1.20174543"], ["65002.20", "1.89089265"]]}}
{"ts_ns": 1725000017200000000, "stream": "depth", "msg": {"e": "depthUpdate", "E": 1725000017200, "s": "BTCUSDT", "U": 1000500, "u": 1000504, "pu": 1000499, "b": [["65002.16", "0.59325101"]], "a": [["65002.29", "1.33029397"]]}}
{"ts_ns": 1725000017223249936, "stream": "trade", "msg": {"e": "trade", "E": 1725000017200, "s": "BTCUSDT", "t": 10000065, "p": "65002.17", "q": "0.47119805", "m": true, "M": true, "T": 1725000017190}}
{"ts_ns": 1725000017300000000, "stream": "depth", "msg": {"e": "depthUpdate", "E": 1725000017300, "s": "BTCUSDT", "U": 1000505, "u": 1000506, "pu": 1000504, "b": [["65002.53", "1.48837917"], ["65002.53", "2.04963875"], ["65002.57", "1.06182976"], ["65002.45", "0.56145334"]], "a": [["65002.65", "1.33803429"], ["65002.63", "0.10394833"], ["65002.70", "1.85093149"], ["65002.71", "0.88531549"], ["65002.67", "2.64833572"], ["65002.68", "0.18293721"]]}}
{"ts_ns": 1725000017310209753, "stream": "trade", "msg": {"e": "trade", "E": 1725000017300, "s": "BTCUSDT", "t": 10000066, "p": "65002.60", "q": "0.32168361", "m": true, "M": true, "T": 1725000017290}}
{"ts_ns": 1725000017400000000, "stream": "depth", "msg": {"e": "depthUpdate", "E": 1725000017400, "s": "BTCUSDT", "U": 1000507, "u": 1000511, "pu": 1000506, "b": [["65002.83", "1.43905332"], ["65002.76", "1.45403846"], ["65002.74", "1.69695335"], ["65002.83", "1.16514382"]], "a": [["65002.92", "0.07818890"], ["65002.99", "0.65706056"], ["65003.04", "2.43206810"], ["65002.94", "0.17577369"], ["65002.97", "1.58829688"], ["65003.02", "1.75196676"]]}}
{"ts_ns": 1725000017411712239, "stream": "trade", "msg": {"e": "trade", "E": 1725000017400, "s": "BTCUSDT", "t": 10000067, "p": "65002.88", "q": "0.32877535", "m": false, "M": true, "T": 1725000017390}}
{"ts_ns": 1725000017500000000, "stream": "depth", "msg": {"e": "depthUpdate", "E": 1725000017500, "s": "BTCUSDT", "U": 1000512, "u": 1000516, "pu": 1000511, "b": [["65003.08", "2.98917615"], ["65003.17", "1.72707633"], ["65003.08", "1.16526756"], ["65003.06", "2.51766676"], ["65003.07", "0.52113609"], ["65003.17", "1.77755853"]], "a": [["65003.34", "2.21431530"]]}}
{"ts_ns": 1725000017540699087, "stream": "trade", "msg": {"e": "trade", "E": 1725000017500, "s": "BTCUSDT", "t": 10000068, "p": "65003.20", "q": "0.35057984", "m": true, "M": true, "T": 1725000017490}}
{"ts_ns": 1725000017600000000, "stream": "depth", "msg": {"e": "depthUpdate", "E": 1725000017600, "s": "BTCUSDT", "U": 1000517, "u": 1000521, "pu": 1000516, "b": [["65003.61", "0.52667030"], ["65003.65", "0.27077213"], ["65003.62", "1.80498836"], ["65003.65", "1.57934554"]], "a": [["65003.67", "0.99520198"], ["65003.76", "0.60439315"], ["65003.69", "1.02227713"], ["65003.69", "2.75634236"], ["65003.80", "2.60465129"]]}}
{"ts_ns": 1725000017610912785, "stream": "trade", "msg": {"e": "trade", "E": 1725000017600, "s": "BTCUSDT", "t": 10000069, "p": "65003.66", "q": "0.45869485", "m": true, "M": true, "T": 1725000017590}}
{"ts_ns": 1725000017700000000, "stream": "depth", "msg": {"e": "depthUpdate", "E": 1725000017700, "s": "BTCUSDT", "U": 1000522, "u": 1000526, "pu": 1000521, "b": [["65003.90", "2.82576964"]], "a": [["65004.09", "1.75804999"], ["65004.08", "0.90529546"], ["65004.05", "2.92758201"]]}}
{"ts_ns": 1725000017800000000, "stream": "depth", "msg": {"e": "depthUpdate", "E": 1725000017800, "s": "BTCUSDT", "U": 1000527, "u": 1000530, "pu": 1000526, "b": [["65004.25", "0.52260801"], ["65004.22", "2.08068119"], ["65004.16", "1.84112696"], ["65004.25", "0.66971164"]], "a": [["65004.41", "2.44336271"], ["65004.38", "0.92046969"], ["65004.43", "0.88355179"], ["65004.34", "2.18649287"], ["65004.43", "2.84609448"], ["65004.38", "2.55227090"]]}}
{"ts_ns": 1725000017900000000, "stream": "depth", "msg": {"e": "depthUpdate", "E": 1725000017900, "s": "BTCUSDT", "U": 1000531, "u": 1000535, "pu": 1000530, "b": [["65003.69", "2.42642078"], ["65003.74", "0.66268575"], ["65003.74", "0.31233070"], ["65003.76", "0.42193010"], ["65003.72", "0.23341992"]], "a": [["65003.90", "2.94713896"], ["65003.87", "1.90856031"], ["65003.86", "2.46498542"]]}}
{"ts_ns": 1725000018000000000, "stream": "depth", "msg": {"e": "depthUpdate", "E": 1725000018000, "s": "BTCUSDT", "U": 1000536, "u": 1000538, "pu": 1000535, "b": [["65003.75", "2.07952823"], ["65003.73", "0.76997382"], ["65003.77", "2.16124076"]], "a": [["65003.80", "1.15781129"], ["65003.91", "1.25895969"]]}}
{"ts_ns": 1725000018028784355, "stream": "trade", "msg": {"e": "trade", "E": 1725000018000, "s": "BTCUSDT", "t": 10000070, "p": "65003.79", "q": "0.18997757", "m": false, "M": true, "T": 1725000017990}}
{"ts_ns": 1725000018100000000, "stream": "depth", "msg": {"e": "depthUpdate", "E": 1725000018100, "s": "BTCUSDT", "U": 1000539, "u": 1000539, "pu": 1000538, "b": [["65003.99", "2.06148121"], ["65004.09", "1.35386226"], ["65003.99", "2.53728745"], ["65004.07", "0.06023399"], ["65004.07", "2.85498639"]], "a": [["65004.14", "1.02542460"], ["65004.27", "1.12637365"], ["65004.24", "0.22500726"], ["65004.27", "2.93412457"], ["65004.18", "1.78209163"], ["65004.22", "2.67967852"]]}}
{"ts_ns": 1725000018200000000, "stream": "depth", "msg": {"e": "depthUpdate", "E": 1725000018200, "s": "BTCUSDT", "U": 1000540, "u": 1000543, "pu": 1000539, "b": [["65004.41", "1.30260115"], ["65004.55", "0.30377343"]], "a": [["65004.60", "2.92319526"], ["65004.63", "2.09159011"], ["65004.68", "2.77672080"], ["65004.65", "0.79579431"], ["65004.61", "0.89220194"]]}}
{"ts_ns": 1725000018227367221, "stream": "trade", "msg": {"e": "trade", "E": 1725000018200, "s": "BTCUSDT", "t": 10000071, "p": "65004.56", "q": "0.42008740", "m": true, "M": true, "T": 1725000018190}}
{"ts_ns": 1725000018300000000, "stream": "depth", "msg": {"e": "depthUpdate", "E": 1725000018300, "s": "BTCUSDT", "U": 1000544, "u": 1000544, "pu": 1000543, "b": [["65004.37", "2.47169192"], ["65004.31", "1.80064658"], ["65004.38", "0.29096069"], ["65004.38", "0.51249658"]], "a": [["65004.47", "2.93117309"]]}}
{"ts_ns": 1725000018400000000, "stream": "depth", "msg": {"e": "depthUpdate", "E": 1725000018400, "s": "BTCUSDT", "U": 1000545, "u": 1000545, "pu": 1000544, "b": [["65004.15", "2.68463245"], ["65004.18", "0.27341063"], ["65004.14", "1.16258135"], ["65004.17", "2.65647808"]], "a": [["65004.29", "0.55974882"], ["65004.24", "0.78988790"], ["65004.31", "0.79020243"], ["65004.37", "0.80568598"]]}}
{"ts_ns": 1725000018447739374, "stream": "trade", "msg": {"e": "trade", "E": 1725000018400, "s": "BTCUSDT", "t": 10000072, "p": "65004.23", "q": "0.04376795", "m": false, "M": true, "T": 1725000018390}}
{"ts_ns": 1725000018500000000, "stream": "depth", "msg": {"e": "depthUpdate", "E": 1725000018500, "s": "BTCUSDT", "U": 1000546, "u": 1000550, "pu": 1000545, "b": [["65004.05", "0.18295124"], ["65004.07", "2.45521564"], ["65004.07", "2.89688311"], ["65004.03", "2.60068204"], ["65004.06", "1.71814287"]], "a": [["65004.18", "1.42878684"], ["65004.16", "1.18441310"]]}}
{"ts_ns": 1725000018600000000, "stream": "depth", "msg": {"e": "depthUpdate", "E": 1725000018600, "s": "BTCUSDT", "U": 1000551, "u": 1000551, "pu": 1000550, "b": [["65004.03", "2.94826429"], ["65004.11", "0.36084562"], ["65004.01", "1.34711921"], ["65004.11", "2.91649464"], ["65004.01", "0.57817825"]], "a": [["65004.15", "1.27012470"], ["65004.25", "1.30617974"], ["65004.28", "1.88167864"], ["65004.28", "1.78514296"], ["65004.20", "2.73241346"]]}}
{"ts_ns": 1725000018700000000, "stream": "depth", "msg": {"e": "depthUpdate", "E": 1725000018700, "s": "BTCUSDT", "U": 1000552, "u": 1000552, "pu": 1000551, "b": [["65003.64", "0.97838042"], ["65003.68", "1.55906453"], ["65003.58", "2.62039876"], ["65003.60", "2.10123636"], ["65003.63", "1.56768603"]], "a": [["65003.80", "0.33755653"], ["65003.76", "0.44459922"], ["65003.83", "1.74803126"], ["65003.75", "2.77478450"]]}}
{"ts_ns": 1725000018800000000, "stream": "depth", "msg": {"e": "depthUpdate", "E": 1725000018800, "s": "BTCUSDT", "U": 1000553, "u": 1000553, "pu": 1000552, "b": [["65003.87", "1.23267011"], ["65003.95", "1.96436301"], ["65003.92", "1.82688646"], ["65004.01", "0.51659918"], ["65003.95", "0.43155801"]], "a": [["65004.12", "2.04243859"], ["65004.09", "0.11634760"], ["65004.17", "2.63687290"]]}}
{"ts_ns": 1725000018900000000, "stream": "depth", "msg": {"e": "depthUpdate", "E": 1725000018900, "s": "BTCUSDT", "U": 1000554, "u": 1000554, "pu": 1000553, "b": [["65004.26", "1.01359824"], ["65004.14", "0.90916486"], ["65004.22", "2.52853971"]], "a": [["65004.41", "2.08854853"], ["65004.29", "2.91748993"], ["65004.31", "0.40315656"]]}}
{"ts_ns": 1725000019000000000, "stream": "depth", "msg": {"e": "depthUpdate", "E": 1725000019000, "s": "BTCUSDT", "U": 1000555, "u": 1000558, "pu": 1000554, "b": [["65004.42", "1.25031818"], ["65004.43", "0.26786055"], ["65004.46", "0.63417151"]], "a": [["65004.68", "1.22151108"], ["65004.62", "2.27847989"], ["65004.68", "1.12173063"]]}}
{"ts_ns": 1725000019011668460, "stream": "trade", "msg": {"e": "trade", "E": 1725000019000, "s": "BTCUSDT", "t": 10000073, "p": "65004.53", "q": "0.35507513", "m": false, "M": true, "T": 1725000018990}}
{"ts_ns": 1725000019100000000, "stream": "depth", "msg": {"e": "depthUpdate", "E": 1725000019100, "s": "BTCUSDT", "U": 1000559, "u": 1000560, "pu": 1000558, "b": [["65004.81", "0.52121207"], ["65004.67", "2.49878980"], ["65004.68", "0.17288255"], ["65004.81", "1.36934600"], ["65004.67", "1.08112525"]], "a": [["65004.86", "0.82193250"], ["65004.96", "1.39265539"], ["65004.89", "1.90622943"], ["65004.84", "2.04352308"], ["65004.86", "1.11740028"]]}}
{"ts_ns": 1725000019200000000, "stream": "depth", "msg": {"e": "depthUpdate", "E": 1725000019200, "s": "BTCUSDT", "U": 1000561, "u": 1000562, "pu": 1000560, "b": [["65005.19", "1.04927970"], ["65005.25", "2.51296131"], ["65005.23", "2.24688340"], ["65005.16", "0.27117576"]], "a": [["65005.29", "1.15969701"], ["65005.31", "2.56146398"], ["65005.41", "2.89475283"], ["65005.42", "0.66405323"], ["65005.32", "2.03308574"]]}}
{"ts_ns": 1725000019228481562, "stream": "trade", "msg": {"e": "trade", "E": 1725000019200, "s": "BTCUSDT", "t": 10000074, "p": "65005.28", "q": "0.43245034", "m": true, "M": true, "T": 1725000019190}}
{"ts_ns": 1725000019300000000, "stream": "depth", "msg": {"e": "depthUpdate", "E": 1725000019300, "s": "BTCUSDT", "U": 1000563, "u": 1000566, "pu": 1000562, "b": [["65005.59", "2.40259442"], ["65005.65", "0.75717132"], ["65005.56", "2.82901490"], ["65005.57", "2.90107333"], ["65005.58", "0.82613567"], ["65005.54", "1.12942636"]], "a": [["65005.75", "1.37699406"], ["65005.73", "1.40009405"]]}}
{"ts_ns": 1725000019400000000, "stream": "depth", "msg": {"e": "depthUpdate", "E": 1725000019400, "s": "BTCUSDT", "U": 1000567, "u": 1000571, "pu": 1000566, "b": [["65005.50", "2.99828814"]], "a": [["65005.73", "2.51813526"]]}}
{"ts_ns": 1725000019500000000, "stream": "depth", "msg": {"e": "depthUpdate", "E": 1725000019500, "s": "BTCUSDT", "U": 1000572, "u": 1000576, "pu": 1000571, "b": [["65005.68", "1.44521526"], ["65005.64", "2.96508290"], ["65005.59", "0.97541121"]], "a": [["65005.75", "0.78344072"], ["65005.82", "2.85656339"], ["65005.81", "0.89637334"], ["65005.73", "1.55188076"], ["65005.74", "2.69906113"], ["65005.83", "2.57194608"]]}}
{"ts_ns": 1725000019600000000, "stream": "depth", "msg": {"e": "depthUpdate", "E": 1725000019600, "s": "BTCUSDT", "U": 1000577, "u": 1000580, "pu": 1000576, "b": [["65005.74", "0.07636581"], ["65005.78", "2.99240730"], ["65005.81", "2.72073469"], ["65005.79", "1.16482476"], ["65005.85", "1.74907111"], ["65005.76", "2.44804410"]], "a": [["65005.92", "2.17964963"], ["65005.90", "2.05895433"]]}}
{"ts_ns": 1725000019700000000, "stream": "depth", "msg": {"e": "depthUpdate", "E": 1725000019700, "s": "BTCUSDT", "U": 1000581, "u": 1000584, "pu": 1000580, "b": [["65006.18", "0.90058449"], ["65006.24", "2.52191608"], ["65006.12", "1.67474413"], ["65006.22", "0.29280919"], ["65006.24", "2.22275667"], ["65006.15", "2.42503161"]], "a": [["65006.40", "2.73787429"], ["65006.38", "2.69877347"], ["65006.38", "0.26789947"]]}}
{"ts_ns": 1725000019721608143, "stream": "trade", "msg": {"e": "trade", "E": 1725000019700, "s": "BTCUSDT", "t": 10000075, "p": "65006.27", "q": "0.44353493", "m": false, "M": true, "T": 1725000019690}}
{"ts_ns": 1725000019800000000, "stream": "depth", "msg": {"e": "depthUpdate", "E": 1725000019800, "s": "BTCUSDT", "U": 1000585, "u": 1000587, "pu": 1000584, "b": [["65006.28", "0.16103086"], ["65006.25", "1.75072386"], ["65006.26", "0.21364721"], ["65006.21", "0.58363141"]], "a": [["65006.38", "2.60249326"]]}}
{"ts_ns": 1725000019821022315, "stream": "trade", "msg": {"e": "trade", "E": 1725000019800, "s": "BTCUSDT", "t": 10000076, "p": "65006.36", "q": "0.43555372", "m": true, "M": true, "T": 1725000019790}}
{"ts_ns": 1725000019900000000, "stream": "depth", "msg": {"e": "depthUpdate", "E": 1725000019900, "s": "BTCUSDT", "U": 1000588, "u": 1000589, "pu": 1000587, "b": [["65006.75", "2.67853537"], ["65006.77", "0.42967246"], ["65006.71", "2.14700537"]], "a": [["65006.98", "0.24243440"], ["65006.91", "1.89309832"], ["65006.88", "0.94024222"], ["65006.86", "0.01414050"]]}}
{"ts_ns": 1725000019912314940, "stream": "trade", "msg": {"e": "trade", "E": 1725000019900, "s": "BTCUSDT", "t": 10000077, "p": "65006.85", "q": "0.08005912", "m": true, "M": true, "T": 1725000019890}}
{"ts_ns": 1725000020000000000, "stream": "depth", "msg": {"e": "depthUpdate", "E": 1725000020000, "s": "BTCUSDT", "U": 1000590, "u": 1000591, "pu": 1000589, "b": [["65006.89", "1.28707635"], ["65006.88", "1.14994926"], ["65006.95", "1.60134781"], ["65006.84", "1.11930422"], ["65006.95", "2.67601918"], ["65006.83", "2.49968600"]], "a": [["65007.00", "0.05374838"], ["65006.97", "1.88006079"], ["65007.00", "0.67879713"], ["65007.11", "1.03304932"]]}}
{"ts_ns": 1725000020026739636, "stream": "trade", "msg": {"e": "trade", "E": 1725000020000, "s": "BTCUSDT", "t": 10000078, "p": "65006.96", "q": "0.15375143", "m": true, "M": true, "T": 1725000019990}}
{"ts_ns": 1725000020100000000, "stream": "depth", "msg": {"e": "depthUpdate", "E": 1725000020100, "s": "BTCUSDT", "U": 1000592, "u": 1000592, "pu": 1000591, "b": [["65006.64", "1.56086524"], ["65006.67", "1.01350545"], ["65006.61", "2.06034046"]], "a": [["65006.79", "1.02819852"], ["65006.91", "1.47053605"], ["65006.89", "0.56527810"], ["65006.91", "2.75461623"]]}}
{"ts_ns": 1725000020200000000, "stream": "depth", "msg": {"e": "depthUpdate", "E": 1725000020200, "s": "BTCUSDT", "U": 1000593, "u": 1000594, "pu": 1000592, "b": [["65006.36", "0.06573982"], ["65006.39", "0.50695423"]], "a": [["65006.54", "2.13333027"], ["65006.61", "0.11209028"]]}}
{"ts_ns": 1725000020300000000, "stream": "depth", "msg": {"e": "depthUpdate", "E": 1725000020300, "s": "BTCUSDT", "U": 1000595, "u": 1000597, "pu": 1000594, "b": [["65006.65", "2.98404070"], ["65006.64", "0.32434035"], ["65006.61", "0.05922530"], ["65006.63", "0.34736948"], ["65006.67", "1.14076129"]], "a": [["65006.84", "0.75821488"]]}}
{"ts_ns": 1725000020400000000, "stream": "depth", "msg": {"e": "depthUpdate", "E": 1725000020400, "s": "BTCUSDT", "U": 1000598, "u": 1000599, "pu": 1000597, "b": [["65006.90", "1.26261437"], ["65006.93", "1.98744890"], ["65006.90", "1.86839333"], ["65006.83", "0.41149057"], ["65006.81", "2.69586578"], ["65006.86", "2.15629867"]], "a": [["65006.97", "0.84812030"]]}}
{"ts_ns": 1725000020500000000, "stream": "depth", "msg": {"e": "depthUpdate", "E": 1725000020500, "s": "BTCUSDT", "U": 1000600, "u": 1000603, "pu": 1000599, "b": [["65006.51", "1.56943832"], ["65006.61", "1.07376551"]], "a": [["65006.72", "0.88605360"], ["65006.66", "1.64441629"], ["65006.80", "0.62308195"]]}}
{"ts_ns": 1725000020600000000, "stream": "depth", "msg": {"e": "depthUpdate", "E": 1725000020600, "s": "BTCUSDT", "U": 1000604, "u": 1000606, "pu": 1000603, "b": [["65006.36", "2.72064013"]], "a": [["65006.52", "1.72245830"], ["65006.46", "0.44743348"], ["65006.40", "2.33857867"], ["65006.40", "2.17069085"], ["65006.40", "2.71433815"], ["65006.49", "0.69348086"]]}}
{"ts_ns": 1725000020700000000, "stream": "depth", "msg": {"e": "depthUpdate", "E": 1725000020700, "s": "BTCUSDT", "U": 1000607, "u": 1000609, "pu": 1000606, "b": [["65006.00", "0.52410543"]], "a": [["65006.15", "2.55674606"]]}}
{"ts_ns": 1725000020746417033, "stream": "trade", "msg": {"e": "trade", "E": 1725000020700, "s": "BTCUSDT", "t": 10000079, "p": "65006.14", "q": "0.36953156", "m": true, "M": true, "T": 1725000020690}}
{"ts_ns": 1725000020800000000, "stream": "depth", "msg": {"e": "depthUpdate", "E": 1725000020800, "s": "BTCUSDT", "U": 1000610, "u": 1000610, "pu": 1000609, "b": [["65005.54", "0.51153683"], ["65005.59", "2.68358285"]], "a": [["65005.75", "0.80492820"], ["65005.77", "0.27885395"], ["65005.79", "1.02816817"], ["65005.67", "1.20233254"], ["65005.73", "0.81549927"], ["65005.72", "2.06970729"]]}}
{"ts_ns": 1725000020900000000, "stream": "depth", "msg": {"e": "depthUpdate", "E": 1725000020900, "s": "BTCUSDT", "U": 1000611, "u": 1000614, "pu": 1000610, "b": [["65005.77", "2.08850962"], ["65005.79", "2.94470751"]], "a": [["65005.94", "0.47818619"]]}}
{"ts_ns": 1725000021000000000, "stream": "depth", "msg": {"e": "depthUpdate", "E": 1725000021000, "s": "BTCUSDT", "U": 1000615, "u": 1000619, "pu": 1000614, "b": [["65005.70", "0.54378168"], ["65005.71", "2.33749288"], ["65005.68", "0.08644869"], ["65005.67", "2.63985074"], ["65005.66", "2.92033374"]], "a": [["65005.81", "1.44923897"], ["65005.86", "0.33881244"], ["65005.85", "1.32206364"], ["65005.80", "0.78483860"], ["65005.84", "0.03708064"], ["65005.92", "2.03378676"]]}}
{"ts_ns": 1725000021100000000, "stream": "depth", "msg": {"e": "depthUpdate", "E": 1725000021100, "s": "BTCUSDT", "U": 1000620, "u": 1000624, "pu": 1000619, "b": [["65005.86", "1.01490193"], ["65005.91", "2.06472493"]], "a": [["65006.10", "0.28572642"], ["65006.11", "2.17995591"], ["65006.08", "1.03724846"], ["65006.11", "1.92421336"], ["65006.03", "2.51709906"], ["65006.09", "2.67618564"]]}}
{"ts_ns": 1725000021200000000, "stream": "depth", "msg": {"e": "depthUpdate", "E": 1725000021200, "s": "BTCUSDT", "U": 1000625, "u": 1000625, "pu": 1000624, "b": [["65006.00", "1.40786681"], ["65006.06", "2.60824690"]], "a": [["65006.16", "2.25429000"], ["65006.20", "0.72267545"], ["65006.19", "0.15105214"], ["65006.18", "1.65148671"], ["65006.21", "1.20983098"]]}}
{"ts_ns": 1725000021231809316, "stream": "trade", "msg": {"e": "trade", "E": 1725000021200, "s": "BTCUSDT", "t": 10000080, "p": "65006.14", "q": "0.28694443", "m": true, "M": true, "T": 1725000021190}}
{"ts_ns": 1725000021300000000, "stream": "depth", "msg": {"e": "depthUpdate", "E": 1725000021300, "s": "BTCUSDT", "U": 1000626, "u": 1000629, "pu": 1000625, "b": [["65005.97", "1.96011901"]], "a": [["65006.11", "1.21031898"], ["65006.10", "1.67139303"], ["65006.10", "2.47772628"], ["65006.22", "1.81260983"]]}}
{"ts_ns": 1725000021400000000, "stream": "depth", "msg": {"e": "depthUpdate", "E": 1725000021400, "s": "BTCUSDT", "U": 1000630, "u": 1000632, "pu": 1000629, "b": [["65006.37", "2.01442311"], ["65006.42", "1.09002743"], ["65006.47", "2.44976606"], ["65006.34", "1.36337995"], ["65006.39", "2.30224920"]], "a": [["65006.58", "1.41940104"], ["65006.59", "1.08988364"]]}}
{"ts_ns": 1725000021500000000, "stream": "depth", "msg": {"e": "depthUpdate", "E": 1725000021500, "s": "BTCUSDT", "U": 1000633, "u": 1000633, "pu": 1000632, "b": [["65006.68", "1.06541694"], ["65006.63", "2.89330105"]], "a": [["65006.79", "1.64307175"]]}}
{"ts_ns": 1725000021508135164, "stream": "trade", "msg": {"e": "trade", "E": 1725000021500, "s": "BTCUSDT", "t": 10000081, "p": "65006.73", "q": "0.08291353", "m": true, "M": true, "T": 1725000021490}}
{"ts_ns": 1725000021600000000, "stream": "depth", "msg": {"e": "depthUpdate", "E": 1725000021600, "s": "BTCUSDT", "U": 1000634, "u": 1000637, "pu": 1000633, "b": [["65006.31", "0.36223742"], ["65006.21", "1.17868947"], ["65006.27", "2.47366243"], ["65006.31", "2.15036374"], ["65006.33", "2.27144803"]], "a": [["65006.36", "2.77987959"], ["65006.49", "2.01642532"]]}}
{"ts_ns": 1725000021631232851, "stream": "trade", "msg": {"e": "trade", "E": 1725000021600, "s": "BTCUSDT", "t": 10000082, "p": "65006.35", "q": "0.29506877", "m": true, "M": true, "T": 1725000021590}}
{"ts_ns": 1725000021700000000, "stream": "depth", "msg": {"e": "depthUpdate", "E": 1725000021700, "s": "BTCUSDT", "U": 1000638, "u": 1000641, "pu": 1000637, "b": [["65005.76", "2.80592484"], ["65005.71", "1.75536213"], ["65005.70", "1.52499870"], ["65005.70", "2.73054446"], ["65005.73", "1.73566316"], ["65005.73", "2.44573246"]], "a": [["65005.87", "1.16221674"]]}}
{"ts_ns": 1725000021800000000, "stream": "depth", "msg": {"e": "depthUpdate", "E": 1725000021800, "s": "BTCUSDT", "U": 1000642, "u": 1000644, "pu": 1000641, "b": [["65005.75", "2.74773073"], ["65005.72", "0.74471637"], ["65005.78", "2.89078061"], ["65005.80", "1.35853712"]], "a": [["65005.88", "0.41454002"], ["65005.95", "2.10004285"], ["65005.97", "1.53688387"], ["65005.99", "2.10448293"]]}}
{"ts_ns": 1725000021900000000, "stream": "depth", "msg": {"e": "depthUpdate", "E": 1725000021900, "s": "BTCUSDT", "U": 1000645, "u": 1000649, "pu": 1000644, "b": [["65005.88", "2.14315361"], ["65005.87", "1.03588074"]], "a": [["65006.09", "0.39801519"], ["65006.10", "1.95025916"]]}}
{"ts_ns": 1725000022000000000, "stream": "depth", "msg": {"e": "depthUpdate", "E": 1725000022000, "s": "BTCUSDT", "U": 1000650, "u": 1000654, "pu": 1000649, "b": [["65005.90", "0.34621576"], ["65005.96", "1.68684063"], ["65005.92", "1.71191458"], ["65005.91", "2.13037089"], ["65005.91", "2.24360617"], ["65005.88", "1.60170841"]], "a": [["65006.17", "2.54190327"], ["65006.15", "0.03831155"], ["65006.04", "0.07581642"]]}}
{"ts_ns": 1725000022045979996, "stream": "trade", "msg": {"e": "trade", "E": 1725000022000, "s": "BTCUSDT", "t": 10000083, "p": "65006.01", "q": "0.13422216", "m": true, "M": true, "T": 1725000021990}}
{"ts_ns": 1725000022100000000, "stream": "depth", "msg": {"e": "depthUpdate", "E": 1725000022100, "s": "BTCUSDT", "U": 1000655, "u": 1000657, "pu": 1000654, "b": [["65006.08", "2.35307220"], ["65006.16", "2.26078184"]], "a": [["65006.21", "1.07604731"]]}}
{"ts_ns": 1725000022200000000, "stream": "depth", "msg": {"e": "depthUpdate", "E": 1725000022200, "s": "BTCUSDT", "U": 1000658, "u": 1000662, "pu": 1000657, "b": [["65006.43", "0.67292216"], ["65006.46", "1.68381166"], ["65006.53", "1.53276691"], ["65006.44", "2.39646526"], ["65006.52", "2.07880823"], ["65006.56", "2.77945443"]], "a": [["65006.64", "1.24969871"], ["65006.70", "2.92746817"], ["65006.63", "2.89749964"], ["65006.58", "0.03889571"], ["65006.62", "0.60926167"]]}}
{"ts_ns": 1725000022300000000, "stream": "depth", "msg": {"e": "depthUpdate", "E": 1725000022300, "s": "BTCUSDT", "U": 1000663, "u": 1000666, "pu": 1000662, "b": [["65006.78", "1.94289716"], ["65006.77", "1.76515602"], ["65006.78", "1.81016093"], ["65006.77", "2.17474356"], ["65006.86", "0.88253317"], ["65006.87", "2.95035997"]], "a": [["65006.92", "0.56092974"], ["65006.93", "2.20523846"], ["65006.92", "1.13159468"], ["65006.97", "0.83733674"], ["65006.95", "0.39019959"], ["65007.00", "2.53804259"]]}}
{"ts_ns": 1725000022332294966, "stream": "trade", "msg": {"e": "trade", "E": 1725000022300, "s": "BTCUSDT", "t": 10000084, "p": "65006.90", "q": "0.07824804", "m": true, "M": true, "T": 1725000022290}}
{"ts_ns": 1725000022400000000, "stream": "depth", "msg": {"e": "depthUpdate", "E": 1725000022400, "s": "BTCUSDT", "U": 1000667, "u": 1000669, "pu": 1000666, "b": [["65006.86", "1.98567063"], ["65006.92", "2.36972455"], ["65006.91", "1.07425676"], ["65006.87", "2.12304468"], ["65006.91", "0.65988605"], ["65006.97", "1.56181886"]], "a": [["65007.13", "1.51542105"], ["65007.07", "1.62924047"], ["65007.07", "0.27583666"], ["65007.04", "2.65019022"], ["65007.11", "0.99565054"]]}}
{"ts_ns": 1725000022415659614, "stream": "trade", "msg": {"e": "trade", "E": 1725000022400, "s": "BTCUSDT", "t": 10000085, "p": "65007.01", "q": "0.30952202", "m": false, "M": true, "T": 1725000022390}}
{"ts_ns": 1725000022500000000, "stream": "depth", "msg": {"e": "depthUpdate", "E": 1725000022500, "s": "BTCUSDT", "U": 1000670, "u": 1000674, "pu": 1000669, "b": [["65007.30", "2.00681540"], ["65007.24", "0.72104363"], ["65007.21", "1.84110329"], ["65007.22", "0.73148149"], ["65007.31", "2.04765408"], ["65007.26", "1.14411782"]], "a": [["65007.45", "2.83496301"]]}}
{"ts_ns": 1725000022537254712, "stream": "trade", "msg": {"e": "trade", "E": 1725000022500, "s": "BTCUSDT", "t": 10000086, "p": "65007.32", "q": "0.01332816", "m": false, "M": true, "T": 1725000022490}}
{"ts_ns": 1725000022600000000, "stream": "depth", "msg": {"e": "depthUpdate", "E": 1725000022600, "s": "BTCUSDT", "U": 1000675, "u": 1000679, "pu": 1000674, "b": [["65007.61", "0.88930191"], ["65007.51", "0.57753716"], ["65007.53", "0.24703634"], ["65007.60", "0.50218443"]], "a": [["65007.75", "1.61392449"], ["65007.63", "1.88079923"], ["65007.66", "2.01100538"], ["65007.75", "0.63952540"]]}}
{"ts_ns": 1725000022700000000, "stream": "depth", "msg": {"e": "depthUpdate", "E": 1725000022700, "s": "BTCUSDT", "U": 1000680, "u": 1000680, "pu": 1000679, "b": [["65007.20", "1.30571329"], ["65007.19", "2.81925333"], ["65007.21", "2.05813062"], ["65007.32", "1.37767571"], ["65007.27", "0.11365894"], ["65007.31", "0.16280421"]], "a": [["65007.46", "0.75572400"], ["65007.35", "1.72488688"], ["65007.37", "2.73295972"], ["65007.40", "1.16409781"], ["65007.44", "1.21334406"], ["65007.39", "0.05067290"]]}}
{"ts_ns": 1725000022800000000, "stream": "depth", "msg": {"e": "depthUpdate", "E": 1725000022800, "s": "BTCUSDT", "U": 1000681, "u": 1000685, "pu": 1000680, "b": [["65006.82", "2.26788179"], ["65006.74", "0.13655056"], ["65006.70", "0.21776833"], ["65006.69", "1.50851085"], ["65006.79", "2.36067569"], ["65006.79", "1.81969752"]], "a": [["65006.89", "2.29582272"], ["65006.92", "1.14424072"], ["65006.98", "1.98216949"], ["65006.92", "0.46897042"], ["65006.88", "0.40914438"]]}}
{"ts_ns": 1725000022837622949, "stream": "trade", "msg": {"e": "trade", "E": 1725000022800, "s": "BTCUSDT", "t": 10000087, "p": "65006.84", "q": "0.31738879", "m": false, "M": true, "T": 1725000022790}}
{"ts_ns": 1725000022900000000, "stream": "depth", "msg": {"e": "depthUpdate", "E": 1725000022900, "s": "BTCUSDT", "U": 1000686, "u": 1000688, "pu": 1000685, "b": [["65007.16", "1.66520924"]], "a": [["65007.32", "0.12531942"], ["65007.40", "1.78996466"], ["65007.39", "1.64257635"], ["65007.32", "0.91407346"], ["65007.42", "2.22429145"]]}}
{"ts_ns": 1725000023000000000, "stream": "depth", "msg": {"e": "depthUpdate", "E": 1725000023000, "s": "BTCUSDT", "U": 1000689, "u": 1000690, "pu": 1000688, "b": [["65007.18", "0.48286307"], ["65007.17", "1.85065477"], ["65007.16", "0.58297865"], ["65007.18", "2.01293373"], ["65007.11", "2.55675338"], ["65007.07", "2.25312544"]], "a": [["65007.30", "1.38379561"], ["65007.30", "0.21943372"], ["65007.32", "0.20208827"], ["65007.23", "0.59225278"], ["65007.31", "1.46157123"]]}}
{"ts_ns": 1725000023009604372, "stream": "trade", "msg": {"e": "trade", "E": 1725000023000, "s": "BTCUSDT", "t": 10000088, "p": "65007.21", "q": "0.11803189", "m": false, "M": true, "T": 1725000022990}}
{"ts_ns": 1725000023100000000, "stream": "depth", "msg": {"e": "depthUpdate", "E": 1725000023100, "s": "BTCUSDT", "U": 1000691, "u": 1000695, "pu": 1000690, "b": [["65006.70", "1.35193793"], ["65006.68", "1.97826675"]], "a": [["65006.90", "1.75250980"], ["65006.88", "1.70058568"], ["65006.91", "0.94899948"]]}}
{"ts_ns": 1725000023200000000, "stream": "depth", "msg": {"e": "depthUpdate", "E": 1725000023200, "s": "BTCUSDT", "U": 1000696, "u": 1000696, "pu": 1000695, "b": [["65006.47", "1.92251563"], ["65006.54", "2.52033018"]], "a": [["65006.62", "2.03874054"], ["65006.65", "2.63365749"], ["65006.67", "1.33607392"], ["65006.72", "0.91641539"], ["65006.68", "0.32649791"], ["65006.70", "1.81988300"]]}}
{"ts_ns": 1725000023300000000, "stream": "depth", "msg": {"e": "depthUpdate", "E": 1725000023300, "s": "BTCUSDT", "U": 1000697, "u": 1000698, "pu": 1000696, "b": [["65006.86", "2.65900750"], ["65006.96", "2.18227610"]], "a": [["65007.13", "0.05589088"], ["65007.07", "1.89487948"], ["65007.12", "1.74567147"]]}}
{"ts_ns": 1725000023400000000, "stream": "depth", "msg": {"e": "depthUpdate", "E": 1725000023400, "s": "BTCUSDT", "U": 1000699, "u": 1000703, "pu": 1000698, "b": [["65006.64", "1.63040797"]], "a": [["65006.78", "1.41631185"], ["65006.82", "0.44589895"], ["65006.76", "0.66991994"], ["65006.82", "1.76880226"], ["65006.83", "0.87299748"]]}}
{"ts_ns": 1725000023500000000, "stream": "depth", "msg": {"e": "depthUpdate", "E": 1725000023500, "s": "BTCUSDT", "U": 1000704, "u": 1000708, "pu": 1000703, "b": [["65006.27", "1.98803547"], ["65006.14", "2.89200080"], ["65006.18", "2.05248497"]], "a": [["65006.41", "1.54241004"], ["65006.36", "0.47766725"], ["65006.38", "2.84613549"], ["65006.39", "2.61658546"], ["65006.31", "2.20775943"]]}}
{"ts_ns": 1725000023600000000, "stream": "depth", "msg": {"e": "depthUpdate", "E": 1725000023600, "s": "BTCUSDT", "U": 1000709, "u": 1000711, "pu": 1000708, "b": [["65005.80", "0.79307135"], ["65005.78", "0.12842532"], ["65005.78", "1.55365569"], ["65005.69", "1.08375409"]], "a": [["65005.90", "2.75370583"], ["65005.97", "0.13931237"]]}}
{"ts_ns": 1725000023700000000, "stream": "depth", "msg": {"e": "depthUpdate", "E": 1725000023700, "s": "BTCUSDT", "U": 1000712, "u": 1000714, "pu": 1000711, "b": [["65005.28", "0.82048595"], ["65005.30", "0.78994821"], ["65005.33", "1.71048046"], ["65005.35", "1.96102594"], ["65005.36", "1.76303647"]], "a": [["65005.57", "2.50640720"], ["65005.51", "0.75475923"], ["65005.57", "0.66869776"], ["65005.49", "1.05869402"], ["65005.56", "1.03509697"], ["65005.55", "1.44633027"]]}}
{"ts_ns": 1725000023800000000, "stream": "depth", "msg": {"e": "depthUpdate", "E": 1725000023800, "s": "BTCUSDT", "U": 1000715, "u": 1000719, "pu": 1000714, "b": [["65005.76", "0.23126468"], ["65005.69", "0.84242853"], ["65005.77", "0.56071703"], ["65005.74", "1.80606083"]], "a": [["65005.94", "0.35499067"], ["65005.84", "1.24384106"]]}}
{"ts_ns": 1725000023808606031, "stream": "trade", "msg": {"e": "trade", "E": 1725000023800, "s": "BTCUSDT", "t": 10000089, "p": "65005.80", "q": "0.23992851", "m": true, "M": true, "T": 1725000023790}}
{"ts_ns": 1725000023900000000, "stream": "depth", "msg": {"e": "depthUpdate", "E": 1725000023900, "s": "BTCUSDT", "U": 1000720, "u": 1000724, "pu": 1000719, "b": [["65005.42", "0.12943299"], ["65005.36", "1.77704298"], ["65005.43", "1.88862127"], ["65005.45", "2.67239301"]], "a": [["65005.49", "0.16773601"]]}}
{"ts_ns": 1725000023913082114, "stream": "trade", "msg": {"e": "trade", "E": 1725000023900, "s": "BTCUSDT", "t": 10000090, "p": "65005.46", "q": "0.20332270", "m": true, "M": true, "T": 1725000023890}}
{"ts_ns": 1725000024000000000, "stream": "depth", "msg": {"e": "depthUpdate", "E": 1725000024000, "s": "BTCUSDT", "U": 1000725, "u": 1000727, "pu": 1000724, "b": [["65005.81", "2.97832747"], ["65005.77", "1.44500520"]], "a": [["65005.95", "2.49109072"], ["65006.01", "0.42813641"], ["65006.01", "2.46135954"], ["65005.94", "1.86963522"]]}}
{"ts_ns": 1725000024100000000, "stream": "depth", "msg": {"e": "depthUpdate", "E": 1725000024100, "s": "BTCUSDT", "U": 1000728, "u": 1000729, "pu": 1000727, "b": [["65006.03", "1.77178797"], ["65006.09", "1.13463406"], ["65006.10", "0.32571034"]], "a": [["65006.17", "1.56813403"], ["65006.28", "1.51307858"], ["65006.20", "2.47954256"], ["65006.23", "0.28889573"]]}}
{"ts_ns": 1725000024200000000, "stream": "depth", "msg": {"e": "depthUpdate", "E": 1725000024200, "s": "BTCUSDT", "U": 1000730, "u": 1000734, "pu": 1000729, "b": [["65006.10", "0.35254922"], ["65006.15", "1.97817783"], ["65006.08", "1.81042395"], ["65006.09", "0.00360062"], ["65006.10", "2.03567808"]], "a": [["65006.30", "1.56613269"], ["65006.29", "2.62447290"], ["65006.35", "1.58944956"], ["65006.27", "2.81526488"], ["65006.31", "2.36866676"]]}}
{"ts_ns": 1725000024240530347, "stream": "trade", "msg": {"e": "trade", "E": 1725000024200, "s": "BTCUSDT", "t": 10000091, "p": "65006.24", "q": "0.45402158", "m": true, "M": true, "T": 1725000024190}}
{"ts_ns": 1725000024300000000, "stream": "depth", "msg": {"e": "depthUpdate", "E": 1725000024300, "s": "BTCUSDT", "U": 1000735, "u": 1000738, "pu": 1000734, "b": [["65005.71", "2.57715974"], ["65005.81", "1.79487705"], ["65005.77", "1.22594011"], ["65005.82", "0.01640836"]], "a": [["65005.98", "2.36826745"], ["65005.96", "1.56762189"]]}}
{"ts_ns": 1725000024400000000, "stream": "depth", "msg": {"e": "depthUpdate", "E": 1725000024400, "s": "BTCUSDT", "U": 1000739, "u": 1000742, "pu": 1000738, "b": [["65005.94", "1.08680937"], ["65005.98", "1.27821477"], ["65005.91", "0.76089818"], ["65005.87", "1.60831467"], ["65005.91", "1.09693228"], ["65005.96", "2.97539602"]], "a": [["65006.08", "2.26491570"], ["65006.08", "1.65631485"], ["65006.10", "1.44740327"]]}}
{"ts_ns": 1725000024438239470, "stream": "trade", "msg": {"e": "trade", "E": 1725000024400, "s": "BTCUSDT", "t": 10000092, "p": "65006.01", "q": "0.49426562", "m": false, "M": true, "T": 1725000024390}}
{"ts_ns": 1725000024500000000, "stream": "depth", "msg": {"e": "depthUpdate", "E": 1725000024500, "s": "BTCUSDT", "U": 1000743, "u": 1000746, "pu": 1000742, "b": [["65006.13", "0.68931391"], ["65006.12", "2.09793433"], ["65006.22", "0.30083585"], ["65006.16", "1.20168272"], ["65006.19", "2.40256120"], ["65006.15", "2.09117223"]], "a": [["65006.37", "0.15615839"]]}}
{"ts_ns": 1725000024543672957, "stream": "trade", "msg": {"e": "trade", "E": 1725000024500, "s": "BTCUSDT", "t": 10000093, "p": "65006.24", "q": "0.04645320", "m": true, "M": true, "T": 1725000024490}}
{"ts_ns": 1725000024600000000, "stream": "depth", "msg": {"e": "depthUpdate", "E": 1725000024600, "s": "BTCUSDT", "U": 1000747, "u": 1000750, "pu": 1000746, "b": [["65006.66", "0.78927599"], ["65006.62", "0.24011921"], ["65006.67", "2.17348414"], ["65006.53", "2.95334430"]], "a": [["65006.78", "1.96852569"]]}}
{"ts_ns": 1725000024641095705, "stream": "trade", "msg": {"e": "trade", "E": 1725000024600, "s": "BTCUSDT", "t": 10000094, "p": "65006.67", "q": "0.38703062", "m": true, "M": true, "T": 1725000024590}}
{"ts_ns": 1725000024700000000, "stream": "depth", "msg": {"e": "depthUpdate", "E": 1725000024700, "s": "BTCUSDT", "U": 1000751, "u": 1000754, "pu": 1000750, "b": [["65006.47", "2.41172973"], ["65006.57", "0.58423948"]], "a": [["65006.75", "1.79854474"], ["65006.71", "2.09534920"], ["65006.72", "0.50844868"], ["65006.63", "1.07921999"], ["65006.73", "0.00086182"], ["65006.65", "0.26052844"]]}}
{"ts_ns": 1725000024727805541, "stream": "trade", "msg": {"e": "trade", "E": 1725000024700, "s": "BTCUSDT", "t": 10000095, "p": "65006.62", "q": "0.19817642", "m": true, "M": true, "T": 1725000024690}}
{"ts_ns": 1725000024800000000, "stream": "depth", "msg": {"e": "depthUpdate", "E": 1725000024800, "s": "BTCUSDT", "U": 1000755, "u": 1000759, "pu": 1000754, "b": [["65005.99", "0.27049757"], ["65006.09", "2.17841613"], ["65006.05", "2.74502692"], ["65006.08", "1.04242527"], ["65006.00", "0.82952355"], ["65006.04", "2.88917142"]], "a": [["65006.22", "2.78914152"]]}}
{"ts_ns": 1725000024900000000, "stream": "depth", "msg": {"e": "depthUpdate", "E": 1725000024900, "s": "BTCUSDT", "U": 1000760, "u": 1000762, "pu": 1000759, "b": [["65005.73", "0.21715791"], ["65005.77", "1.01989768"], ["65005.80", "2.40882673"], ["65005.77", "2.62833914"], ["65005.68", "2.38016777"]], "a": [["65005.87", "2.08257558"]]}}
{"ts_ns": 1725000025000000000, "stream": "depth", "msg": {"e": "depthUpdate", "E": 1725000025000, "s": "BTCUSDT", "U": 1000763, "u": 1000767, "pu": 1000762, "b": [["65005.67", "1.37654529"], ["65005.72", "2.68957147"]], "a": [["65005.94", "0.08205209"], ["65005.82", "0.77345929"], ["65005.87", "1.90098539"]]}}
{"ts_ns": 1725000025100000000, "stream": "depth", "msg": {"e": "depthUpdate", "E": 1725000025100, "s": "BTCUSDT", "U": 1000768, "u": 1000769, "pu": 1000767, "b": [["65006.01", "1.60695572"], ["65005.98", "2.49653113"], ["65006.06", "0.86186875"], ["65006.03", "2.02109375"]], "a": [["65006.24", "1.02597863"], ["65006.19", "2.79418872"], ["65006.18", "0.94161834"]]}}
{"ts_ns": 1725000025139501202, "stream": "trade", "msg": {"e": "trade", "E": 1725000025100, "s": "BTCUSDT", "t": 10000096, "p": "65006.10", "q": "0.47361194", "m": true, "M": true, "T": 1725000025090}}
{"ts_ns": 1725000025200000000, "stream": "depth", "msg": {"e": "depthUpdate", "E": 1725000025200, "s": "BTCUSDT", "U": 1000770, "u": 1000773, "pu": 1000769, "b": [["65006.30", "2.61822750"], ["65006.30", "0.68762260"]], "a": [["65006.48", "0.74908630"], ["65006.44", "1.06808212"], ["65006.47", "0.32006787"], ["65006.49", "0.23546272"], ["65006.45", "1.47799459"], ["65006.35", "2.29273264"]]}}
{"ts_ns": 1725000025300000000, "stream": "depth", "msg": {"e": "depthUpdate", "E": 1725000025300, "s": "BTCUSDT", "U": 1000774, "u": 1000774, "pu": 1000773, "b": [["65006.63", "1.47702113"], ["65006.54", "2.69099932"], ["65006.55", "0.82419910"]], "a": [["65006.72", "2.95318405"], ["65006.84", "1.53340091"], ["65006.76", "0.66627835"], ["65006.79", "0.38473785"], ["65006.78", "2.39780975"]]}}
{"ts_ns": 1725000025400000000, "stream": "depth", "msg": {"e": "depthUpdate", "E": 1725000025400, "s": "BTCUSDT", "U": 1000775, "u": 1000779, "pu": 1000774, "b": [["65006.08", "2.05901594"], ["65006.19", "1.37158810"], ["65006.20", "2.09473370"]], "a": [["65006.30", "0.94695380"], ["65006.23", "0.03545994"], ["65006.26", "1.13828401"], ["65006.24", "0.97630860"]]}}
{"ts_ns": 1725000025500000000, "stream": "depth", "msg": {"e": "depthUpdate", "E": 1725000025500, "s": "BTCUSDT", "U": 1000780, "u": 1000782, "pu": 1000779, "b": [["65005.86", "1.41403609"], ["65005.81", "1.02928938"], ["65005.88", "1.49631005"]], "a": [["65005.95", "1.25727883"], ["65006.04", "1.11692888"]]}}
{"ts_ns": 1725000025600000000, "stream": "depth", "msg": {"e": "depthUpdate", "E": 1725000025600, "s": "BTCUSDT", "U": 1000783, "u": 1000785, "pu": 1000782, "b": [["65005.76", "2.05803574"], ["65005.72", "0.29960922"], ["65005.81", "2.41226274"], ["65005.77", "1.29665626"], ["65005.79", "0.58818964"]], "a": [["65005.99", "2.87744376"], ["65005.89", "1.41896107"]]}}
{"ts_ns": 1725000025629287773, "stream": "trade", "msg": {"e": "trade", "E": 1725000025600, "s": "BTCUSDT", "t": 10000097, "p": "65005.86", "q": "0.49778532", "m": false, "M": true, "T": 1725000025590}}
{"ts_ns": 1725000025700000000, "stream": "depth", "msg": {"e": "depthUpdate", "E": 1725000025700, "s": "BTCUSDT", "U": 1000786, "u": 1000789, "pu": 1000785, "b": [["65005.65", "1.19520571"], ["65005.54", "0.49002564"], ["65005.62", "2.44145421"], ["65005.58", "2.51691513"], ["65005.64", "1.34956446"]], "a": [["65005.72", "0.77930737"], ["65005.72", "1.68105010"], ["65005.81", "2.43004764"], ["65005.72", "0.05950600"], ["65005.68", "1.05327147"]]}}
{"ts_ns": 1725000025800000000, "stream": "depth", "msg": {"e": "depthUpdate", "E": 1725000025800, "s": "BTCUSDT", "U": 1000790, "u": 1000794, "pu": 1000789, "b": [["65005.25", "1.61531476"], ["65005.23", "0.85382620"], ["65005.30", "2.01957852"], ["65005.28", "2.32423310"], ["65005.28", "2.66889735"]], "a": [["65005.43", "1.84099132"], ["65005.44", "1.89513657"], ["65005.39", "2.60477295"], ["65005.47", "2.42315143"], ["65005.42", "1.26544946"], ["65005.46", "1.71491272"]]}}
{"ts_ns": 1725000025900000000, "stream": "depth", "msg": {"e": "depthUpdate", "E": 1725000025900, "s": "BTCUSDT", "U": 1000795, "u": 1000795, "pu": 1000794, "b": [["65004.88", "0.95063473"], ["65004.89", "2.13130046"], ["65004.84", "1.93393288"]], "a": [["65004.99", "2.66307542"], ["65005.07", "2.58841945"]]}}
{"ts_ns": 1725000025940387519, "stream": "trade", "msg": {"e": "trade", "E": 1725000025900, "s": "BTCUSDT", "t": 10000098, "p": "65004.94", "q": "0.22569404", "m": true, "M": true, "T": 1725000025890}}
{"ts_ns": 1725000026000000000, "stream": "depth", "msg": {"e": "depthUpdate", "E": 1725000026000, "s": "BTCUSDT", "U": 1000796, "u": 1000797, "pu": 1000795, "b": [["65005.25", "1.98606764"], ["65005.17", "2.10209079"]], "a": [["65005.31", "0.63171447"], ["65005.36", "0.30902794"], ["65005.31", "2.81038099"], ["65005.37", "1.64530123"], ["65005.30", "2.31280112"], ["65005.38", "2.29498912"]]}}
{"ts_ns": 1725000026018612873, "stream": "trade", "msg": {"e": "trade", "E": 1725000026000, "s": "BTCUSDT", "t": 10000099, "p": "65005.29", "q": "0.04307132", "m": false, "M": true, "T": 1725000025990}}
{"ts_ns": 1725000026100000000, "stream": "depth", "msg": {"e": "depthUpdate", "E": 1725000026100, "s": "BTCUSDT", "U": 1000798, "u": 1000800, "pu": 1000797, "b": [["65004.94", "1.87944205"], ["65004.99", "1.58022701"], ["65004.99", "0.08571388"], ["65004.91", "1.07052373"], ["65004.87", "0.97560395"], ["65004.94", "1.40158043"]], "a": [["65005.16", "1.62175248"], ["65005.07", "1.64563582"], ["65005.05", "2.90862679"]]}}
{"ts_ns": 1725000026200000000, "stream": "depth", "msg": {"e": "depthUpdate", "E": 1725000026200, "s": "BTCUSDT", "U": 1000801, "u": 1000802, "pu": 1000800, "b": [["65004.99", "1.90755341"], ["65005.01", "1.30493211"], ["65005.00", "1.91858475"], ["65005.06", "2.72676946"]], "a": [["65005.19", "1.61900437"], ["65005.24", "0.26866207"], ["65005.16", "1.09734997"], ["65005.16", "0.46715262"], ["65005.12", "0.00027704"], ["65005.25", "2.27488035"]]}}
{"ts_ns": 1725000026220244288, "stream": "trade", "msg": {"e": "trade", "E": 1725000026200, "s": "BTCUSDT", "t": 10000100, "p": "65005.11", "q": "0.00515024", "m": false, "M": true, "T": 1725000026190}}
{"ts_ns": 1725000026300000000, "stream": "depth", "msg": {"e": "depthUpdate", "E": 1725000026300, "s": "BTCUSDT", "U": 1000803, "u": 1000806, "pu": 1000802, "b": [["65004.81", "0.69364618"], ["65004.90", "1.64463659"], ["65004.87", "1.23520761"], ["65004.82", "1.31131910"]], "a": [["65004.95", "0.48980849"], ["65005.03", "1.93797240"], ["65005.05", "1.13507418"]]}}
{"ts_ns": 1725000026329336005, "stream": "trade", "msg": {"e": "trade", "E": 1725000026300, "s": "BTCUSDT", "t": 10000101, "p": "65004.91", "q": "0.25878842", "m": false, "M": true, "T": 1725000026290}}
{"ts_ns": 1725000026400000000, "stream": "depth", "msg": {"e": "depthUpdate", "E": 1725000026400, "s": "BTCUSDT", "U": 1000807, "u": 1000809, "pu": 1000806, "b": [["65004.99", "0.56400188"], ["65005.04", "0.54722154"], ["65005.01", "0.33106905"], ["65004.98", "1.85318824"], ["65005.01", "2.10141779"]], "a": [["65005.14", "0.56336833"], ["65005.07", "0.45644792"], ["65005.15", "0.06639266"]]}}
{"ts_ns": 1725000026500000000, "stream": "depth", "msg": {"e": "depthUpdate", "E": 1725000026500, "s": "BTCUSDT", "U": 1000810, "u": 1000812, "pu": 1000809, "b": [["65004.71", "0.02461227"], ["65004.81", "0.45205108"], ["65004.75", "0.65156426"], ["65004.76", "0.93473006"], ["65004.70", "1.49518727"], ["65004.77", "1.39105340"]], "a": [["65004.96", "0.09521136"], ["65004.85", "2.53063890"], ["65004.86", "0.16811503"], ["65004.96", "1.17726533"]]}}
{"ts_ns": 1725000026600000000, "stream": "depth", "msg": {"e": "depthUpdate", "E": 1725000026600, "s": "BTCUSDT", "U": 1000813, "u": 1000814, "pu": 1000812, "b": [["65004.38", "0.03784646"], ["65004.39", "2.14404756"], ["65004.45", "2.31367600"]], "a": [["65004.60", "0.74148657"], ["65004.53", "0.59753963"], ["65004.64", "2.31298790"], ["65004.61", "1.99802365"]]}}
{"ts_ns": 1725000026627113599, "stream": "trade", "msg": {"e": "trade", "E": 1725000026600, "s": "BTCUSDT", "t": 10000102, "p": "65004.52", "q": "0.15674257", "m": false, "M": true, "T": 1725000026590}}
{"ts_ns": 1725000026700000000, "stream": "depth", "msg": {"e": "depthUpdate", "E": 1725000026700, "s": "BTCUSDT", "U": 1000815, "u": 1000816, "pu": 1000814, "b": [["65004.50", "1.64873983"]], "a": [["65004.67", "0.75993822"], ["65004.76", "0.89643925"], ["65004.71", "2.66255873"], ["65004.79", "2.00008435"], ["65004.67", "0.70789751"], ["65004.72", "0.97354046"]]}}
{"ts_ns": 1725000026719528760, "stream": "trade", "msg": {"e": "trade", "E": 1725000026700, "s": "BTCUSDT", "t": 10000103, "p": "65004.65", "q": "0.19850834", "m": true, "M": true, "T": 1725000026690}}
{"ts_ns": 1725000026800000000, "stream": "depth", "msg": {"e": "depthUpdate", "E": 1725000026800, "s": "BTCUSDT", "U": 1000817, "u": 1000817, "pu": 1000816, "b": [["65005.04", "2.06521962"], ["65005.09", "1.11419599"], ["65005.10", "0.74616677"], ["65005.04", "0.27420466"], ["65005.02", "1.01526629"]], "a": [["65005.25", "1.87539699"], ["65005.13", "1.06655303"], ["65005.15", "2.10398442"], ["65005.25", "0.32217497"], ["65005.20", "0.69802389"], ["65005.21", "2.36568548"]]}}
{"ts_ns": 1725000026900000000, "stream": "depth", "msg": {"e": "depthUpdate", "E": 1725000026900, "s": "BTCUSDT", "U": 1000818, "u": 1000821, "pu": 1000817, "b": [["65005.28", "1.07450249"]], "a": [["65005.38", "0.75208872"], ["65005.36", "1.45590640"], ["65005.43", "1.67707437"], ["65005.44", "2.09111332"], ["65005.39", "1.70010520"], ["65005.44", "1.04299404"]]}}
{"ts_ns": 1725000027000000000, "stream": "depth", "msg": {"e": "depthUpdate", "E": 1725000027000, "s": "BTCUSDT", "U": 1000822, "u": 1000824, "pu": 1000821, "b": [["65005.69", "0.20662975"], ["65005.69", "1.34815260"], ["65005.58", "0.79004781"], ["65005.66", "1.36223694"], ["65005.59", "1.91407819"]], "a": [["65005.79", "2.20097322"], ["65005.87", "0.05615957"], ["65005.86", "1.09222559"], ["65005.82", "0.71635967"], ["65005.84", "0.19002527"]]}}
{"ts_ns": 1725000027100000000, "stream": "depth", "msg": {"e": "depthUpdate", "E": 1725000027100, "s": "BTCUSDT", "U": 1000825, "u": 1000828, "pu": 1000824, "b": [["65005.28", "1.65440342"], ["65005.31", "0.84938725"], ["65005.34", "1.92271179"], ["65005.39", "0.28876889"], ["65005.30", "0.20003953"], ["65005.27", "2.81339861"]], "a": [["65005.44", "2.62047833"], ["65005.45", "0.32116551"], ["65005.45", "0.29626076"], ["65005.51", "1.92525500"]]}}
{"ts_ns": 1725000027133877279, "stream": "trade", "msg": {"e": "trade", "E": 1725000027100, "s": "BTCUSDT", "t": 10000104, "p": "65005.41", "q": "0.35095570", "m": false, "M": true, "T": 1725000027090}}
{"ts_ns": 1725000027200000000, "stream": "depth", "msg": {"e": "depthUpdate", "E": 1725000027200, "s": "BTCUSDT", "U": 1000829, "u": 1000829, "pu": 1000828, "b": [["65005.26", "0.03925833"], ["65005.13", "0.62621428"], ["65005.20", "2.78521116"], ["65005.14", "0.23987041"], ["65005.15", "1.91675015"]], "a": [["65005.34", "1.67405967"], ["65005.43", "1.24785961"], ["65005.34", "2.38274873"], ["65005.29", "2.47092890"], ["65005.33", "1.58706249"], ["65005.40", "0.21116439"]]}}
{"ts_ns": 1725000027215488807, "stream": "trade", "msg": {"e": "trade", "E": 1725000027200, "s": "BTCUSDT", "t": 10000105, "p": "65005.29", "q": "0.04946251", "m": true, "M": true, "T": 1725000027190}}
{"ts_ns": 1725000027300000000, "stream": "depth", "msg": {"e": "depthUpdate", "E": 1725000027300, "s": "BTCUSDT", "U": 1000830, "u": 1000834, "pu": 1000829, "b": [["65005.06", "0.74628909"], ["65005.06", "2.84251003"]], "a": [["65005.26", "2.24758307"], ["65005.24", "2.23832513"], ["65005.30", "1.91587290"], ["65005.23", "2.02347769"], ["65005.29", "1.99572706"]]}}
{"ts_ns": 1725000027400000000, "stream": "depth", "msg": {"e": "depthUpdate", "E": 1725000027400, "s": "BTCUSDT", "U": 1000835, "u": 1000836, "pu": 1000834, "b": [["65005.37", "1.01253861"], ["65005.43", "1.60170143"], ["65005.36", "1.32903651"], ["65005.40", "2.70745491"], ["65005.37", "2.97438897"]], "a": [["65005.52", "2.53456204"], ["65005.53", "2.29255310"], ["65005.53", "2.47846493"], ["65005.52", "1.82524011"]]}}
{"ts_ns": 1725000027500000000, "stream": "depth", "msg": {"e": "depthUpdate", "E": 1725000027500, "s": "BTCUSDT", "U": 1000837, "u": 1000838, "pu": 1000836, "b": [["65005.29", "1.08002563"], ["65005.26", "1.34249937"], ["65005.27", "0.00058688"], ["65005.33", "2.94886941"], ["65005.24", "0.04890734"]], "a": [["65005.37", "2.98023603"], ["65005.39", "0.01970649"], ["65005.38", "0.64446844"], ["65005.40", "0.06510411"], ["65005.48", "2.83004372"], ["65005.48", "0.82787141"]]}}
{"ts_ns": 1725000027600000000, "stream": "depth", "msg": {"e": "depthUpdate", "E": 1725000027600, "s": "BTCUSDT", "U": 1000839, "u": 1000843, "pu": 1000838, "b": [["65005.39", "0.11320890"], ["65005.35", "0.46832132"], ["65005.36", "1.10124868"], ["65005.31", "0.74957072"], ["65005.36", "2.43322271"]], "a": [["65005.43", "1.71146148"], ["65005.51", "2.75364541"]]}}
{"ts_ns": 1725000027700000000, "stream": "depth", "msg": {"e": "depthUpdate", "E": 1725000027700, "s": "BTCUSDT", "U": 1000844, "u": 1000846, "pu": 1000843, "b": [["65005.56", "2.69707229"], ["65005.58", "1.72869739"]], "a": [["65005.85", "0.28609216"], ["65005.81", "0.90117976"], ["65005.82", "2.42502352"], ["65005.77", "0.23543219"]]}}
{"ts_ns": 1725000027723440509, "stream": "trade", "msg": {"e": "trade", "E": 1725000027700, "s": "BTCUSDT", "t": 10000106, "p": "65005.70", "q": "0.40875371", "m": false, "M": true, "T": 1725000027690}}
{"ts_ns": 1725000027800000000, "stream": "depth", "msg": {"e": "depthUpdate", "E": 1725000027800, "s": "BTCUSDT", "U": 1000847, "u": 1000847, "pu": 1000846, "b": [["65005.96", "2.54843450"], ["65005.92", "0.03430314"]], "a": [["65006.20", "1.89658086"], ["65006.08", "0.91435018"], ["65006.08", "0.95794962"], ["65006.17", "0.44874006"], ["65006.16", "2.09330596"], ["65006.10", "0.15155944"]]}}
{"ts_ns": 1725000027900000000, "stream": "depth", "msg": {"e": "depthUpdate", "E": 1725000027900, "s": "BTCUSDT", "U": 1000848, "u": 1000851, "pu": 1000847, "b": [["65006.45", "0.27024886"], ["65006.47", "0.86934909"], ["65006.47", "0.44403720"], ["65006.48", "0.24763534"], ["65006.44", "2.23594511"]], "a": [["65006.63", "1.19757390"], ["65006.56", "1.19558111"], ["65006.61", "2.32147541"], ["65006.57", "2.28609876"], ["65006.62", "1.67788853"]]}}
{"ts_ns": 1725000028000000000, "stream": "depth", "msg": {"e": "depthUpdate", "E": 1725000028000, "s": "BTCUSDT", "U": 1000852, "u": 1000856, "pu": 1000851, "b": [["65006.15", "0.73873752"], ["65006.22", "0.79877127"], ["65006.17", "0.97023492"], ["65006.09", "1.72805471"], ["65006.22", "2.01524266"]], "a": [["65006.31", "1.09580293"], ["65006.28", "0.96221509"], ["65006.34", "1.96622957"], ["65006.37", "0.91445654"], ["65006.30", "1.84866298"], ["65006.37", "1.32663032"]]}}
{"ts_ns": 1725000028004011681, "stream": "trade", "msg": {"e": "trade", "E": 1725000028000, "s": "BTCUSDT", "t": 10000107, "p": "65006.25", "q": "0.11751131", "m": false, "M": true, "T": 1725000027990}}
{"ts_ns": 1725000028100000000, "stream": "depth", "msg": {"e": "depthUpdate", "E": 1725000028100, "s": "BTCUSDT", "U": 1000857, "u": 1000858, "pu": 1000856, "b": [["65006.38", "0.16361404"]], "a": [["65006.60", "2.78018909"]]}}
{"ts_ns": 1725000028200000000, "stream": "depth", "msg": {"e": "depthUpdate", "E": 1725000028200, "s": "BTCUSDT", "U": 1000859, "u": 1000861, "pu": 1000858, "b": [["65005.96", "1.35018471"], ["65006.00", "0.99563016"], ["65005.89", "1.61401637"], ["65005.97", "1.63927264"], ["65005.88", "0.77597401"], ["65005.93", "1.86912598"]], "a": [["65006.04", "2.08521343"]]}}
{"ts_ns": 1725000028300000000, "stream": "depth", "msg": {"e": "depthUpdate", "E": 1725000028300, "s": "BTCUSDT", "U": 1000862, "u": 1000865, "pu": 1000861, "b": [["65006.08", "0.76636903"], ["65006.08", "0.85204062"], ["65005.96", "2.08958007"], ["65006.04", "0.15925575"], ["65005.98", "2.83552945"], ["65006.07", "1.16593544"]], "a": [["65006.14", "1.98894491"], ["65006.24", "1.98030112"], ["65006.23", "0.32367430"], ["65006.14", "2.60223133"], ["65006.20", "1.15956968"]]}}
{"ts_ns": 1725000028400000000, "stream": "depth", "msg": {"e": "depthUpdate", "E": 1725000028400, "s": "BTCUSDT", "U": 1000866, "u": 1000870, "pu": 1000865, "b": [["65006.49", "2.60031824"]], "a": [["65006.66", "0.26406201"], ["65006.61", "1.50195247"], ["65006.65", "1.68206262"]]}}
{"ts_ns": 1725000028500000000, "stream": "depth", "msg": {"e": "depthUpdate", "E": 1725000028500, "s": "BTCUSDT", "U": 1000871, "u": 1000871, "pu": 1000870, "b": [["65006.26", "1.46979854"], ["65006.20", "0.47101575"], ["65006.26", "2.05293407"], ["65006.26", "1.87569291"], ["65006.28", "2.98798323"]], "a": [["65006.41", "0.82763484"], ["65006.33", "1.87737709"], ["65006.47", "1.16151177"]]}}
{"ts_ns": 1725000028600000000, "stream": "depth", "msg": {"e": "depthUpdate", "E": 1725000028600, "s": "BTCUSDT", "U": 1000872, "u": 1000872, "pu": 1000871, "b": [["65006.73", "1.02535846"], ["65006.69", "1.97079528"], ["65006.74", "2.18966899"]], "a": [["65006.85", "2.88181708"], ["65006.86", "2.61810441"]]}}
{"ts_ns": 1725000028700000000, "stream": "depth", "msg": {"e": "depthUpdate", "E": 1725000028700, "s": "BTCUSDT", "U": 1000873, "u": 1000876, "pu": 1000872, "b": [["65006.45", "2.72920618"], ["65006.44", "1.34750756"]], "a": [["65006.53", "0.62027182"], ["65006.53", "1.74309210"], ["65006.61", "2.40031518"], ["65006.64", "0.41432892"]]}}
{"ts_ns": 1725000028800000000, "stream": "depth", "msg": {"e": "depthUpdate", "E": 1725000028800, "s": "BTCUSDT", "U": 1000877, "u": 1000881, "pu": 1000876, "b": [["65006.80", "2.79908984"], ["65006.76", "0.47414375"], ["65006.89", "1.67202089"], ["65006.79", "0.35516187"]], "a": [["65006.97", "2.51856753"], ["65006.94", "2.18123860"]]}}
{"ts_ns": 1725000028900000000, "stream": "depth", "msg": {"e": "depthUpdate", "E": 1725000028900, "s": "BTCUSDT", "U": 1000882, "u": 1000885, "pu": 1000881, "b": [["65007.25", "2.80130557"], ["65007.22", "1.91054220"], ["65007.25", "0.82138849"]], "a": [["65007.50", "0.56380081"], ["65007.40", "0.55423949"], ["65007.50", "2.95786678"], ["65007.47", "0.80058784"]]}}
{"ts_ns": 1725000029000000000, "stream": "depth", "msg": {"e": "depthUpdate", "E": 1725000029000, "s": "BTCUSDT", "U": 1000886, "u": 1000887, "pu": 1000885, "b": [["65007.46", "1.07778400"], ["65007.35", "2.33947875"]], "a": [["65007.50", "1.50697376"], ["65007.57", "1.40629049"], ["65007.58", "1.12187820"], ["65007.61", "1.16238086"], ["65007.55", "0.41253817"], ["65007.51", "0.67881918"]]}}
{"ts_ns": 1725000029100000000, "stream": "depth", "msg": {"e": "depthUpdate", "E": 1725000029100, "s": "BTCUSDT", "U": 1000888, "u": 1000888, "pu": 1000887, "b": [["65007.78", "2.01401726"], ["65007.86", "2.27332977"], ["65007.88", "0.53123461"], ["65007.82", "2.60138701"]], "a": [["65007.98", "2.06358811"], ["65008.04", "1.37263479"]]}}
{"ts_ns": 1725000029128170148, "stream": "trade", "msg": {"e": "trade", "E": 1725000029100, "s": "BTCUSDT", "t": 10000108, "p": "65007.91", "q": "0.30435705", "m": false, "M": true, "T": 1725000029090}}
{"ts_ns": 1725000029200000000, "stream": "depth", "msg": {"e": "depthUpdate", "E": 1725000029200, "s": "BTCUSDT", "U": 1000889, "u": 1000891, "pu": 1000888, "b": [["65007.69", "1.60847816"], ["65007.68", "2.62734892"], ["65007.66", "0.11553592"], ["65007.77", "1.35482878"], ["65007.65", "2.63330090"], ["65007.64", "2.98750911"]], "a": [["65007.88", "1.61360743"], ["65007.91", "0.11775487"], ["65007.86", "1.54838005"], ["65007.90", "2.88777693"], ["65007.83", "0.87353809"]]}}
{"ts_ns": 1725000029221438282, "stream": "trade", "msg": {"e": "trade", "E": 1725000029200, "s": "BTCUSDT", "t": 10000109, "p": "65007.80", "q": "0.14367138", "m": true, "M": true, "T": 1725000029190}}
{"ts_ns": 1725000029300000000, "stream": "depth", "msg": {"e": "depthUpdate", "E": 1725000029300, "s": "BTCUSDT", "U": 1000892, "u": 1000895, "pu": 1000891, "b": [["65007.49", "2.71102694"]], "a": [["65007.66", "2.48968051"], ["65007.66", "0.27132242"], ["65007.67", "0.33951476"], ["65007.71", "1.75634316"], ["65007.73", "2.08834243"], ["65007.61", "1.17920014"]]}}
{"ts_ns": 1725000029302671823, "stream": "trade", "msg": {"e": "trade", "E": 1725000029300, "s": "BTCUSDT", "t": 10000110, "p": "65007.57", "q": "0.29556742", "m": true, "M": true, "T": 1725000029290}}
{"ts_ns": 1725000029400000000, "stream": "depth", "msg": {"e": "depthUpdate", "E": 1725000029400, "s": "BTCUSDT", "U": 1000896, "u": 1000899, "pu": 1000895, "b": [["65007.06", "2.72148739"], ["65007.04", "0.49198208"], ["65007.05", "0.37063265"]], "a": [["65007.19", "2.11868013"], ["65007.28", "1.08883017"], ["65007.26", "2.12183736"], ["65007.29", "2.37319978"], ["65007.26", "1.83621760"], ["65007.20", "1.13603589"]]}}
{"ts_ns": 1725000029412467896, "stream": "trade", "msg": {"e": "trade", "E": 1725000029400, "s": "BTCUSDT", "t": 10000111, "p": "65007.18", "q": "0.28318030", "m": true, "M": true, "T": 1725000029390}}
{"ts_ns": 1725000029500000000, "stream": "depth", "msg": {"e": "depthUpdate", "E": 1725000029500, "s": "BTCUSDT", "U": 1000900, "u": 1000901, "pu": 1000899, "b": [["65007.53", "1.25874507"], ["65007.49", "2.19048524"]], "a": [["65007.62", "0.86634161"], ["65007.57", "0.35266194"], ["65007.57", "2.88130164"], ["65007.55", "1.86768098"], ["65007.59", "0.03662329"], ["65007.62", "2.56623317"]]}}
{"ts_ns": 1725000029600000000, "stream": "depth", "msg": {"e": "depthUpdate", "E": 1725000029600, "s": "BTCUSDT", "U": 1000902, "u": 1000902, "pu": 1000901, "b": [["65007.61", "1.76658698"], ["65007.57", "1.36121545"], ["65007.57", "0.23821475"], ["65007.55", "0.01971907"]], "a": [["65007.80", "1.64202483"], ["65007.75", "1.88590628"]]}}
{"ts_ns": 1725000029700000000, "stream": "depth", "msg": {"e": "depthUpdate", "E": 1725000029700, "s": "BTCUSDT", "U": 1000903, "u": 1000904, "pu": 1000902, "b": [["65007.09", "1.04705950"], ["65007.17", "2.56148786"]], "a": [["65007.31", "1.73427815"]]}}
{"ts_ns": 1725000029800000000, "stream": "depth", "msg": {"e": "depthUpdate", "E": 1725000029800, "s": "BTCUSDT", "U": 1000905, "u": 1000907, "pu": 1000904, "b": [["65007.55", "2.98120554"]], "a": [["65007.65", "2.01627149"]]}}
{"ts_ns": 1725000029900000000, "stream": "depth", "msg": {"e": "depthUpdate", "E": 1725000029900, "s": "BTCUSDT", "U": 1000908, "u": 1000912, "pu": 1000907, "b": [["65007.61", "2.24800443"], ["65007.63", "2.79443946"], ["65007.67", "2.30553595"], ["65007.63", "1.10570828"], ["65007.62", "2.46079423"]], "a": [["65007.82", "1.28197152"], ["65007.78", "0.19477760"]]}}
{"ts_ns": 1725000030000000000, "stream": "depth", "msg": {"e": "depthUpdate", "E": 1725000030000, "s": "BTCUSDT", "U": 1000913, "u": 1000913, "pu": 1000912, "b": [["65007.79", "1.24127373"], ["65007.84", "2.08748849"], ["65007.78", "0.17455376"]], "a": [["65007.98", "2.18918556"], ["65007.99", "1.58683987"], ["65007.90", "1.45098895"]]}}
